2021-12-07 11:59:15,539-[logger01.py - 56]-WARNING:waring级别以上的日志信息
2021-12-07 11:59:15,539-[logger01.py - 57]-ERROR:error级别以上的日志信息
2021-12-07 12:01:12,245-[log_utils.py - 50]-WARNING:waring级别以上的日志信息
2021-12-07 12:01:12,246-[log_utils.py - 51]-ERROR:error级别以上的日志信息
2021-12-07 12:34:39,387-[log_utils.py - 46]-WARNING:waring级别以上的日志信息
2021-12-07 12:34:39,387-[log_utils.py - 47]-ERROR:error级别以上的日志信息
2021-12-07 12:34:41,362-[logger02.py - 18]-INFO:该方法异常
2021-12-07 12:35:16,057-[log_utils.py - 46]-WARNING:waring级别以上的日志信息
2021-12-07 12:35:16,057-[log_utils.py - 47]-ERROR:error级别以上的日志信息
2021-12-07 12:35:18,190-[logger02.py - 15]-ERROR:该方法异常
2021-12-07 12:35:18,190-[logger02.py - 16]-ERROR:invalid literal for int() with base 10: '10.0'
Traceback (most recent call last):
  File "D:/PythonWorkSpace/day16/logger02.py", line 12, in <module>
    res = 50 / int(num)
ValueError: invalid literal for int() with base 10: '10.0'
2021-12-07 12:37:25,122-[log_utils.py - 46]-WARNING:waring级别以上的日志信息
2021-12-07 12:37:25,122-[log_utils.py - 47]-ERROR:error级别以上的日志信息
2021-12-07 12:37:31,840-[logger02.py - 15]-ERROR:该方法异常
2021-12-07 12:37:31,840-[logger02.py - 16]-ERROR:division by zero
Traceback (most recent call last):
  File "D:/PythonWorkSpace/day16/logger02.py", line 12, in <module>
    res = 50 / int(num)
ZeroDivisionError: division by zero
2021-12-07 12:38:43,541-[log_utils.py - 46]-WARNING:waring级别以上的日志信息
2021-12-07 12:38:43,541-[log_utils.py - 47]-ERROR:error级别以上的日志信息
2021-12-07 12:38:45,680-[logger02.py - 18]-INFO:该方法异常
2021-12-07 14:44:33,571-[log_utils.py - 46]-WARNING:waring级别以上的日志信息
2021-12-07 14:44:33,571-[log_utils.py - 47]-ERROR:error级别以上的日志信息
2021-12-07 14:44:57,145-[log_utils.py - 46]-WARNING:waring级别以上的日志信息
2021-12-07 14:44:57,145-[log_utils.py - 47]-ERROR:error级别以上的日志信息
2021-12-07 14:47:15,080-[log_utils.py - 46]-WARNING:waring级别以上的日志信息
2021-12-07 14:47:15,080-[log_utils.py - 47]-ERROR:error级别以上的日志信息
2021-12-07 14:48:49,009-[log_utils.py - 46]-WARNING:waring级别以上的日志信息
2021-12-07 14:48:49,009-[log_utils.py - 47]-ERROR:error级别以上的日志信息
2021-12-07 14:48:49,125-[test_login.py - 43]-INFO:测试编号1,测试用例标题登录接口主流程,执行成功!
2021-12-07 14:48:49,246-[test_login.py - 43]-INFO:测试编号3,测试用例标题登录接口用户名为空的场景,执行成功!
2021-12-07 14:48:49,398-[test_login.py - 43]-INFO:测试编号5,测试用例标题登录接口密码为空的场景,执行成功!
2021-12-07 14:52:29,299-[log_utils.py - 46]-WARNING:waring级别以上的日志信息
2021-12-07 14:52:29,300-[log_utils.py - 47]-ERROR:error级别以上的日志信息
2021-12-07 14:52:42,287-[log_utils.py - 46]-WARNING:waring级别以上的日志信息
2021-12-07 14:52:42,287-[log_utils.py - 47]-ERROR:error级别以上的日志信息
2021-12-07 14:53:21,334-[log_utils.py - 46]-WARNING:waring级别以上的日志信息
2021-12-07 14:53:21,334-[log_utils.py - 47]-ERROR:error级别以上的日志信息
2021-12-07 14:53:45,538-[log_utils.py - 46]-WARNING:waring级别以上的日志信息
2021-12-07 14:53:45,538-[log_utils.py - 47]-ERROR:error级别以上的日志信息
2021-12-07 14:53:45,658-[test_login.py - 43]-INFO:测试编号1,测试用例标题登录接口主流程,执行成功!
2021-12-07 14:53:45,744-[test_login.py - 37]-ERROR:测试编号2,测试用例标题登录接口输入错误用户名的场景,执行失败!实际结果{'code': 9999, 'msg': '登录成功'}
2021-12-07 14:53:45,744-[test_login.py - 38]-ERROR:{'code': 1003, 'msg': '用户名或者密码错误'} != {'code': 9999, 'msg': '登录成功'}
- {'code': 1003, 'msg': '用户名或者密码错误'}
+ {'code': 9999, 'msg': '登录成功'}
Traceback (most recent call last):
  File "D:\PythonWorkSpace\day16\homework\test_login.py", line 34, in test_login
    self.assertEqual(eval(case.expect), res_body)  # assert 断言的意思，Equal是相等的意思
  File "D:\python\PyCharm Community Edition 2021.2.3\plugins\python-ce\helpers\pycharm\teamcity\diff_tools.py", line 32, in _patched_equals
    old(self, first, second, msg)
  File "C:\Program Files\Python37\lib\unittest\case.py", line 839, in assertEqual
    assertion_func(first, second, msg=msg)
  File "C:\Program Files\Python37\lib\unittest\case.py", line 1138, in assertDictEqual
    self.fail(self._formatMessage(msg, standardMsg))
  File "C:\Program Files\Python37\lib\unittest\case.py", line 680, in fail
    raise self.failureException(msg)
AssertionError: {'code': 1003, 'msg': '用户名或者密码错误'} != {'code': 9999, 'msg': '登录成功'}
- {'code': 1003, 'msg': '用户名或者密码错误'}
+ {'code': 9999, 'msg': '登录成功'}
2021-12-07 14:53:45,805-[test_login.py - 43]-INFO:测试编号3,测试用例标题登录接口用户名为空的场景,执行成功!
2021-12-07 14:53:45,868-[test_login.py - 37]-ERROR:测试编号4,测试用例标题登录接口密码输入错误的场景,执行失败!实际结果{'code': 9999, 'msg': '登录成功'}
2021-12-07 14:53:45,868-[test_login.py - 38]-ERROR:{'code': 1003, 'msg': '用户名或者密码错误'} != {'code': 9999, 'msg': '登录成功'}
- {'code': 1003, 'msg': '用户名或者密码错误'}
+ {'code': 9999, 'msg': '登录成功'}
Traceback (most recent call last):
  File "D:\PythonWorkSpace\day16\homework\test_login.py", line 34, in test_login
    self.assertEqual(eval(case.expect), res_body)  # assert 断言的意思，Equal是相等的意思
  File "D:\python\PyCharm Community Edition 2021.2.3\plugins\python-ce\helpers\pycharm\teamcity\diff_tools.py", line 32, in _patched_equals
    old(self, first, second, msg)
  File "C:\Program Files\Python37\lib\unittest\case.py", line 839, in assertEqual
    assertion_func(first, second, msg=msg)
  File "C:\Program Files\Python37\lib\unittest\case.py", line 1138, in assertDictEqual
    self.fail(self._formatMessage(msg, standardMsg))
  File "C:\Program Files\Python37\lib\unittest\case.py", line 680, in fail
    raise self.failureException(msg)
AssertionError: {'code': 1003, 'msg': '用户名或者密码错误'} != {'code': 9999, 'msg': '登录成功'}
- {'code': 1003, 'msg': '用户名或者密码错误'}
+ {'code': 9999, 'msg': '登录成功'}
2021-12-07 14:53:45,926-[test_login.py - 43]-INFO:测试编号5,测试用例标题登录接口密码为空的场景,执行成功!
2021-12-07 15:07:40,177-[log_utils.py - 46]-WARNING:waring级别以上的日志信息
2021-12-07 15:07:40,178-[log_utils.py - 47]-ERROR:error级别以上的日志信息
2021-12-07 15:07:53,310-[log_utils.py - 46]-WARNING:waring级别以上的日志信息
2021-12-07 15:07:53,310-[log_utils.py - 47]-ERROR:error级别以上的日志信息
2021-12-07 15:07:53,420-[test_login.py - 42]-INFO:测试编号1,测试用例标题登录接口主流程,执行成功!
2021-12-07 15:07:53,490-[test_login.py - 36]-ERROR:测试编号2,测试用例标题登录接口输入错误用户名的场景,执行失败!实际结果{'code': 9999, 'msg': '登录成功'}
2021-12-07 15:07:53,490-[test_login.py - 37]-ERROR:{'code': 1003, 'msg': '用户名或者密码错误'} != {'code': 9999, 'msg': '登录成功'}
- {'code': 1003, 'msg': '用户名或者密码错误'}
+ {'code': 9999, 'msg': '登录成功'}
Traceback (most recent call last):
  File "D:\PythonWorkSpace\day16\homework\test_login.py", line 33, in test_login
    self.assertEqual(eval(case.expect), res_body)  # assert 断言的意思，Equal是相等的意思
  File "D:\python\PyCharm Community Edition 2021.2.3\plugins\python-ce\helpers\pycharm\teamcity\diff_tools.py", line 32, in _patched_equals
    old(self, first, second, msg)
  File "C:\Program Files\Python37\lib\unittest\case.py", line 839, in assertEqual
    assertion_func(first, second, msg=msg)
  File "C:\Program Files\Python37\lib\unittest\case.py", line 1138, in assertDictEqual
    self.fail(self._formatMessage(msg, standardMsg))
  File "C:\Program Files\Python37\lib\unittest\case.py", line 680, in fail
    raise self.failureException(msg)
AssertionError: {'code': 1003, 'msg': '用户名或者密码错误'} != {'code': 9999, 'msg': '登录成功'}
- {'code': 1003, 'msg': '用户名或者密码错误'}
+ {'code': 9999, 'msg': '登录成功'}
2021-12-07 15:07:53,542-[test_login.py - 42]-INFO:测试编号3,测试用例标题登录接口用户名为空的场景,执行成功!
2021-12-07 15:07:53,591-[test_login.py - 36]-ERROR:测试编号4,测试用例标题登录接口密码输入错误的场景,执行失败!实际结果{'code': 9999, 'msg': '登录成功'}
2021-12-07 15:07:53,591-[test_login.py - 37]-ERROR:{'code': 1003, 'msg': '用户名或者密码错误'} != {'code': 9999, 'msg': '登录成功'}
- {'code': 1003, 'msg': '用户名或者密码错误'}
+ {'code': 9999, 'msg': '登录成功'}
Traceback (most recent call last):
  File "D:\PythonWorkSpace\day16\homework\test_login.py", line 33, in test_login
    self.assertEqual(eval(case.expect), res_body)  # assert 断言的意思，Equal是相等的意思
  File "D:\python\PyCharm Community Edition 2021.2.3\plugins\python-ce\helpers\pycharm\teamcity\diff_tools.py", line 32, in _patched_equals
    old(self, first, second, msg)
  File "C:\Program Files\Python37\lib\unittest\case.py", line 839, in assertEqual
    assertion_func(first, second, msg=msg)
  File "C:\Program Files\Python37\lib\unittest\case.py", line 1138, in assertDictEqual
    self.fail(self._formatMessage(msg, standardMsg))
  File "C:\Program Files\Python37\lib\unittest\case.py", line 680, in fail
    raise self.failureException(msg)
AssertionError: {'code': 1003, 'msg': '用户名或者密码错误'} != {'code': 9999, 'msg': '登录成功'}
- {'code': 1003, 'msg': '用户名或者密码错误'}
+ {'code': 9999, 'msg': '登录成功'}
2021-12-07 15:07:53,650-[test_login.py - 42]-INFO:测试编号5,测试用例标题登录接口密码为空的场景,执行成功!
2021-12-07 15:10:46,000-[log_utils.py - 46]-WARNING:waring级别以上的日志信息
2021-12-07 15:10:46,000-[log_utils.py - 47]-ERROR:error级别以上的日志信息
2021-12-07 15:10:46,129-[test_login.py - 42]-INFO:测试编号1,测试用例标题登录接口主流程,执行成功!
2021-12-07 15:10:46,206-[test_login.py - 36]-ERROR:测试编号2,测试用例标题登录接口输入错误用户名的场景,执行失败!实际结果{'code': 9999, 'msg': '登录成功'}
2021-12-07 15:10:46,206-[test_login.py - 37]-ERROR:{'code': 1003, 'msg': '用户名或者密码错误'} != {'code': 9999, 'msg': '登录成功'}
- {'code': 1003, 'msg': '用户名或者密码错误'}
+ {'code': 9999, 'msg': '登录成功'}
Traceback (most recent call last):
  File "D:\PythonWorkSpace\day16\homework\test_login.py", line 33, in test_login
    self.assertEqual(eval(case.expect), res_body)  # assert 断言的意思，Equal是相等的意思
  File "D:\python\PyCharm Community Edition 2021.2.3\plugins\python-ce\helpers\pycharm\teamcity\diff_tools.py", line 32, in _patched_equals
    old(self, first, second, msg)
  File "C:\Program Files\Python37\lib\unittest\case.py", line 839, in assertEqual
    assertion_func(first, second, msg=msg)
  File "C:\Program Files\Python37\lib\unittest\case.py", line 1138, in assertDictEqual
    self.fail(self._formatMessage(msg, standardMsg))
  File "C:\Program Files\Python37\lib\unittest\case.py", line 680, in fail
    raise self.failureException(msg)
AssertionError: {'code': 1003, 'msg': '用户名或者密码错误'} != {'code': 9999, 'msg': '登录成功'}
- {'code': 1003, 'msg': '用户名或者密码错误'}
+ {'code': 9999, 'msg': '登录成功'}
2021-12-07 15:10:46,268-[test_login.py - 42]-INFO:测试编号3,测试用例标题登录接口用户名为空的场景,执行成功!
2021-12-07 15:10:46,333-[test_login.py - 36]-ERROR:测试编号4,测试用例标题登录接口密码输入错误的场景,执行失败!实际结果{'code': 9999, 'msg': '登录成功'}
2021-12-07 15:10:46,334-[test_login.py - 37]-ERROR:{'code': 1003, 'msg': '用户名或者密码错误'} != {'code': 9999, 'msg': '登录成功'}
- {'code': 1003, 'msg': '用户名或者密码错误'}
+ {'code': 9999, 'msg': '登录成功'}
Traceback (most recent call last):
  File "D:\PythonWorkSpace\day16\homework\test_login.py", line 33, in test_login
    self.assertEqual(eval(case.expect), res_body)  # assert 断言的意思，Equal是相等的意思
  File "D:\python\PyCharm Community Edition 2021.2.3\plugins\python-ce\helpers\pycharm\teamcity\diff_tools.py", line 32, in _patched_equals
    old(self, first, second, msg)
  File "C:\Program Files\Python37\lib\unittest\case.py", line 839, in assertEqual
    assertion_func(first, second, msg=msg)
  File "C:\Program Files\Python37\lib\unittest\case.py", line 1138, in assertDictEqual
    self.fail(self._formatMessage(msg, standardMsg))
  File "C:\Program Files\Python37\lib\unittest\case.py", line 680, in fail
    raise self.failureException(msg)
AssertionError: {'code': 1003, 'msg': '用户名或者密码错误'} != {'code': 9999, 'msg': '登录成功'}
- {'code': 1003, 'msg': '用户名或者密码错误'}
+ {'code': 9999, 'msg': '登录成功'}
2021-12-07 15:10:46,393-[test_login.py - 42]-INFO:测试编号5,测试用例标题登录接口密码为空的场景,执行成功!
2021-12-07 15:13:07,131-[log_utils.py - 46]-WARNING:waring级别以上的日志信息
2021-12-07 15:13:07,132-[log_utils.py - 47]-ERROR:error级别以上的日志信息
2021-12-07 15:13:07,243-[test_login.py - 42]-INFO:测试编号1,测试用例标题登录接口主流程,执行成功!
2021-12-07 15:13:07,322-[test_login.py - 36]-ERROR:测试编号2,测试用例标题登录接口输入错误用户名的场景,执行失败!实际结果{'code': 9999, 'msg': '登录成功'}
2021-12-07 15:13:07,323-[test_login.py - 37]-ERROR:{'code': 1003, 'msg': '用户名或者密码错误'} != {'code': 9999, 'msg': '登录成功'}
- {'code': 1003, 'msg': '用户名或者密码错误'}
+ {'code': 9999, 'msg': '登录成功'}
Traceback (most recent call last):
  File "D:\PythonWorkSpace\day16\homework\test_login.py", line 33, in test_login
    self.assertEqual(eval(case.expect), res_body)  # assert 断言的意思，Equal是相等的意思
  File "D:\python\PyCharm Community Edition 2021.2.3\plugins\python-ce\helpers\pycharm\teamcity\diff_tools.py", line 32, in _patched_equals
    old(self, first, second, msg)
  File "C:\Program Files\Python37\lib\unittest\case.py", line 839, in assertEqual
    assertion_func(first, second, msg=msg)
  File "C:\Program Files\Python37\lib\unittest\case.py", line 1138, in assertDictEqual
    self.fail(self._formatMessage(msg, standardMsg))
  File "C:\Program Files\Python37\lib\unittest\case.py", line 680, in fail
    raise self.failureException(msg)
AssertionError: {'code': 1003, 'msg': '用户名或者密码错误'} != {'code': 9999, 'msg': '登录成功'}
- {'code': 1003, 'msg': '用户名或者密码错误'}
+ {'code': 9999, 'msg': '登录成功'}
2021-12-07 15:13:07,382-[test_login.py - 42]-INFO:测试编号3,测试用例标题登录接口用户名为空的场景,执行成功!
2021-12-07 15:13:07,437-[test_login.py - 36]-ERROR:测试编号4,测试用例标题登录接口密码输入错误的场景,执行失败!实际结果{'code': 9999, 'msg': '登录成功'}
2021-12-07 15:13:07,437-[test_login.py - 37]-ERROR:{'code': 1003, 'msg': '用户名或者密码错误'} != {'code': 9999, 'msg': '登录成功'}
- {'code': 1003, 'msg': '用户名或者密码错误'}
+ {'code': 9999, 'msg': '登录成功'}
Traceback (most recent call last):
  File "D:\PythonWorkSpace\day16\homework\test_login.py", line 33, in test_login
    self.assertEqual(eval(case.expect), res_body)  # assert 断言的意思，Equal是相等的意思
  File "D:\python\PyCharm Community Edition 2021.2.3\plugins\python-ce\helpers\pycharm\teamcity\diff_tools.py", line 32, in _patched_equals
    old(self, first, second, msg)
  File "C:\Program Files\Python37\lib\unittest\case.py", line 839, in assertEqual
    assertion_func(first, second, msg=msg)
  File "C:\Program Files\Python37\lib\unittest\case.py", line 1138, in assertDictEqual
    self.fail(self._formatMessage(msg, standardMsg))
  File "C:\Program Files\Python37\lib\unittest\case.py", line 680, in fail
    raise self.failureException(msg)
AssertionError: {'code': 1003, 'msg': '用户名或者密码错误'} != {'code': 9999, 'msg': '登录成功'}
- {'code': 1003, 'msg': '用户名或者密码错误'}
+ {'code': 9999, 'msg': '登录成功'}
2021-12-07 15:13:07,496-[test_login.py - 42]-INFO:测试编号5,测试用例标题登录接口密码为空的场景,执行成功!
2021-12-07 15:13:34,234-[log_utils.py - 46]-WARNING:waring级别以上的日志信息
2021-12-07 15:13:34,234-[log_utils.py - 47]-ERROR:error级别以上的日志信息
2021-12-07 15:13:34,339-[test_login.py - 42]-INFO:测试编号1,测试用例标题登录接口主流程,执行成功!
2021-12-07 15:13:34,403-[test_login.py - 36]-ERROR:测试编号2,测试用例标题登录接口输入错误用户名的场景,执行失败!实际结果{'code': 9999, 'msg': '登录成功'}
2021-12-07 15:13:34,403-[test_login.py - 37]-ERROR:{'code': 1003, 'msg': '用户名或者密码错误'} != {'code': 9999, 'msg': '登录成功'}
- {'code': 1003, 'msg': '用户名或者密码错误'}
+ {'code': 9999, 'msg': '登录成功'}
Traceback (most recent call last):
  File "D:\PythonWorkSpace\day16\homework\test_login.py", line 33, in test_login
    self.assertEqual(eval(case.expect), res_body)  # assert 断言的意思，Equal是相等的意思
  File "D:\python\PyCharm Community Edition 2021.2.3\plugins\python-ce\helpers\pycharm\teamcity\diff_tools.py", line 32, in _patched_equals
    old(self, first, second, msg)
  File "C:\Program Files\Python37\lib\unittest\case.py", line 839, in assertEqual
    assertion_func(first, second, msg=msg)
  File "C:\Program Files\Python37\lib\unittest\case.py", line 1138, in assertDictEqual
    self.fail(self._formatMessage(msg, standardMsg))
  File "C:\Program Files\Python37\lib\unittest\case.py", line 680, in fail
    raise self.failureException(msg)
AssertionError: {'code': 1003, 'msg': '用户名或者密码错误'} != {'code': 9999, 'msg': '登录成功'}
- {'code': 1003, 'msg': '用户名或者密码错误'}
+ {'code': 9999, 'msg': '登录成功'}
2021-12-07 15:13:34,460-[test_login.py - 42]-INFO:测试编号3,测试用例标题登录接口用户名为空的场景,执行成功!
2021-12-07 15:13:34,509-[test_login.py - 36]-ERROR:测试编号4,测试用例标题登录接口密码输入错误的场景,执行失败!实际结果{'code': 9999, 'msg': '登录成功'}
2021-12-07 15:13:34,509-[test_login.py - 37]-ERROR:{'code': 1003, 'msg': '用户名或者密码错误'} != {'code': 9999, 'msg': '登录成功'}
- {'code': 1003, 'msg': '用户名或者密码错误'}
+ {'code': 9999, 'msg': '登录成功'}
Traceback (most recent call last):
  File "D:\PythonWorkSpace\day16\homework\test_login.py", line 33, in test_login
    self.assertEqual(eval(case.expect), res_body)  # assert 断言的意思，Equal是相等的意思
  File "D:\python\PyCharm Community Edition 2021.2.3\plugins\python-ce\helpers\pycharm\teamcity\diff_tools.py", line 32, in _patched_equals
    old(self, first, second, msg)
  File "C:\Program Files\Python37\lib\unittest\case.py", line 839, in assertEqual
    assertion_func(first, second, msg=msg)
  File "C:\Program Files\Python37\lib\unittest\case.py", line 1138, in assertDictEqual
    self.fail(self._formatMessage(msg, standardMsg))
  File "C:\Program Files\Python37\lib\unittest\case.py", line 680, in fail
    raise self.failureException(msg)
AssertionError: {'code': 1003, 'msg': '用户名或者密码错误'} != {'code': 9999, 'msg': '登录成功'}
- {'code': 1003, 'msg': '用户名或者密码错误'}
+ {'code': 9999, 'msg': '登录成功'}
2021-12-07 15:13:34,559-[test_login.py - 42]-INFO:测试编号5,测试用例标题登录接口密码为空的场景,执行成功!
2021-12-07 15:14:27,911-[log_utils.py - 46]-WARNING:waring级别以上的日志信息
2021-12-07 15:14:27,911-[log_utils.py - 47]-ERROR:error级别以上的日志信息
2021-12-07 15:14:28,013-[test_login.py - 42]-INFO:测试编号1,测试用例标题登录接口主流程,执行成功!
2021-12-07 15:14:28,080-[test_login.py - 36]-ERROR:测试编号2,测试用例标题登录接口输入错误用户名的场景,执行失败!实际结果{'code': 9999, 'msg': '登录成功'}
2021-12-07 15:14:28,081-[test_login.py - 37]-ERROR:{'code': 1003, 'msg': '用户名或者密码错误'} != {'code': 9999, 'msg': '登录成功'}
- {'code': 1003, 'msg': '用户名或者密码错误'}
+ {'code': 9999, 'msg': '登录成功'}
Traceback (most recent call last):
  File "D:\PythonWorkSpace\day16\homework\test_login.py", line 33, in test_login
    self.assertEqual(eval(case.expect), res_body)  # assert 断言的意思，Equal是相等的意思
  File "D:\python\PyCharm Community Edition 2021.2.3\plugins\python-ce\helpers\pycharm\teamcity\diff_tools.py", line 32, in _patched_equals
    old(self, first, second, msg)
  File "C:\Program Files\Python37\lib\unittest\case.py", line 839, in assertEqual
    assertion_func(first, second, msg=msg)
  File "C:\Program Files\Python37\lib\unittest\case.py", line 1138, in assertDictEqual
    self.fail(self._formatMessage(msg, standardMsg))
  File "C:\Program Files\Python37\lib\unittest\case.py", line 680, in fail
    raise self.failureException(msg)
AssertionError: {'code': 1003, 'msg': '用户名或者密码错误'} != {'code': 9999, 'msg': '登录成功'}
- {'code': 1003, 'msg': '用户名或者密码错误'}
+ {'code': 9999, 'msg': '登录成功'}
2021-12-07 15:14:28,136-[test_login.py - 42]-INFO:测试编号3,测试用例标题登录接口用户名为空的场景,执行成功!
2021-12-07 15:14:28,186-[test_login.py - 36]-ERROR:测试编号4,测试用例标题登录接口密码输入错误的场景,执行失败!实际结果{'code': 9999, 'msg': '登录成功'}
2021-12-07 15:14:28,186-[test_login.py - 37]-ERROR:{'code': 1003, 'msg': '用户名或者密码错误'} != {'code': 9999, 'msg': '登录成功'}
- {'code': 1003, 'msg': '用户名或者密码错误'}
+ {'code': 9999, 'msg': '登录成功'}
Traceback (most recent call last):
  File "D:\PythonWorkSpace\day16\homework\test_login.py", line 33, in test_login
    self.assertEqual(eval(case.expect), res_body)  # assert 断言的意思，Equal是相等的意思
  File "D:\python\PyCharm Community Edition 2021.2.3\plugins\python-ce\helpers\pycharm\teamcity\diff_tools.py", line 32, in _patched_equals
    old(self, first, second, msg)
  File "C:\Program Files\Python37\lib\unittest\case.py", line 839, in assertEqual
    assertion_func(first, second, msg=msg)
  File "C:\Program Files\Python37\lib\unittest\case.py", line 1138, in assertDictEqual
    self.fail(self._formatMessage(msg, standardMsg))
  File "C:\Program Files\Python37\lib\unittest\case.py", line 680, in fail
    raise self.failureException(msg)
AssertionError: {'code': 1003, 'msg': '用户名或者密码错误'} != {'code': 9999, 'msg': '登录成功'}
- {'code': 1003, 'msg': '用户名或者密码错误'}
+ {'code': 9999, 'msg': '登录成功'}
2021-12-07 15:14:28,233-[test_login.py - 42]-INFO:测试编号5,测试用例标题登录接口密码为空的场景,执行成功!
2021-12-07 15:22:44,302-[log_utils.py - 46]-WARNING:waring级别以上的日志信息
2021-12-07 15:22:44,303-[log_utils.py - 47]-ERROR:error级别以上的日志信息
2021-12-07 15:23:11,511-[log_utils.py - 46]-WARNING:waring级别以上的日志信息
2021-12-07 15:23:11,511-[log_utils.py - 47]-ERROR:error级别以上的日志信息
2021-12-07 15:23:32,956-[log_utils.py - 46]-WARNING:waring级别以上的日志信息
2021-12-07 15:23:32,957-[log_utils.py - 47]-ERROR:error级别以上的日志信息
2021-12-07 15:25:02,754-[test_login.py - 36]-ERROR:测试编号2,测试用例标题登录接口输入错误用户名的场景,执行失败!实际结果{'code': 9999, 'msg': '登录成功'}
2021-12-07 15:25:02,755-[test_login.py - 37]-ERROR:{'code': 1003, 'msg': '用户名或者密码错误'} != {'code': 9999, 'msg': '登录成功'}
- {'code': 1003, 'msg': '用户名或者密码错误'}
+ {'code': 9999, 'msg': '登录成功'}
Traceback (most recent call last):
  File "D:\PythonWorkSpace\day16\homework\test_login.py", line 33, in test_login
    self.assertEqual(eval(case.expect), res_body)  # assert 断言的意思，Equal是相等的意思
  File "D:\python\PyCharm Community Edition 2021.2.3\plugins\python-ce\helpers\pycharm\teamcity\diff_tools.py", line 32, in _patched_equals
    old(self, first, second, msg)
  File "C:\Program Files\Python37\lib\unittest\case.py", line 839, in assertEqual
    assertion_func(first, second, msg=msg)
  File "C:\Program Files\Python37\lib\unittest\case.py", line 1138, in assertDictEqual
    self.fail(self._formatMessage(msg, standardMsg))
  File "C:\Program Files\Python37\lib\unittest\case.py", line 680, in fail
    raise self.failureException(msg)
AssertionError: {'code': 1003, 'msg': '用户名或者密码错误'} != {'code': 9999, 'msg': '登录成功'}
- {'code': 1003, 'msg': '用户名或者密码错误'}
+ {'code': 9999, 'msg': '登录成功'}
2021-12-07 15:25:02,848-[test_login.py - 42]-INFO:测试编号3,测试用例标题登录接口用户名为空的场景,执行成功!
2021-12-07 15:25:02,899-[test_login.py - 36]-ERROR:测试编号4,测试用例标题登录接口密码输入错误的场景,执行失败!实际结果{'code': 9999, 'msg': '登录成功'}
2021-12-07 15:25:02,899-[test_login.py - 37]-ERROR:{'code': 1003, 'msg': '用户名或者密码错误'} != {'code': 9999, 'msg': '登录成功'}
- {'code': 1003, 'msg': '用户名或者密码错误'}
+ {'code': 9999, 'msg': '登录成功'}
Traceback (most recent call last):
  File "D:\PythonWorkSpace\day16\homework\test_login.py", line 33, in test_login
    self.assertEqual(eval(case.expect), res_body)  # assert 断言的意思，Equal是相等的意思
  File "D:\python\PyCharm Community Edition 2021.2.3\plugins\python-ce\helpers\pycharm\teamcity\diff_tools.py", line 32, in _patched_equals
    old(self, first, second, msg)
  File "C:\Program Files\Python37\lib\unittest\case.py", line 839, in assertEqual
    assertion_func(first, second, msg=msg)
  File "C:\Program Files\Python37\lib\unittest\case.py", line 1138, in assertDictEqual
    self.fail(self._formatMessage(msg, standardMsg))
  File "C:\Program Files\Python37\lib\unittest\case.py", line 680, in fail
    raise self.failureException(msg)
AssertionError: {'code': 1003, 'msg': '用户名或者密码错误'} != {'code': 9999, 'msg': '登录成功'}
- {'code': 1003, 'msg': '用户名或者密码错误'}
+ {'code': 9999, 'msg': '登录成功'}
2021-12-07 15:25:02,952-[test_login.py - 42]-INFO:测试编号5,测试用例标题登录接口密码为空的场景,执行成功!
2021-12-07 15:25:11,827-[log_utils.py - 46]-WARNING:waring级别以上的日志信息
2021-12-07 15:25:11,828-[log_utils.py - 47]-ERROR:error级别以上的日志信息
2021-12-07 15:25:11,939-[test_login.py - 42]-INFO:测试编号1,测试用例标题登录接口主流程,执行成功!
2021-12-07 15:25:12,004-[test_login.py - 36]-ERROR:测试编号2,测试用例标题登录接口输入错误用户名的场景,执行失败!实际结果{'code': 9999, 'msg': '登录成功'}
2021-12-07 15:25:12,004-[test_login.py - 37]-ERROR:{'code': 1003, 'msg': '用户名或者密码错误'} != {'code': 9999, 'msg': '登录成功'}
- {'code': 1003, 'msg': '用户名或者密码错误'}
+ {'code': 9999, 'msg': '登录成功'}
Traceback (most recent call last):
  File "D:\PythonWorkSpace\day16\homework\test_login.py", line 33, in test_login
    self.assertEqual(eval(case.expect), res_body)  # assert 断言的意思，Equal是相等的意思
  File "D:\python\PyCharm Community Edition 2021.2.3\plugins\python-ce\helpers\pycharm\teamcity\diff_tools.py", line 32, in _patched_equals
    old(self, first, second, msg)
  File "C:\Program Files\Python37\lib\unittest\case.py", line 839, in assertEqual
    assertion_func(first, second, msg=msg)
  File "C:\Program Files\Python37\lib\unittest\case.py", line 1138, in assertDictEqual
    self.fail(self._formatMessage(msg, standardMsg))
  File "C:\Program Files\Python37\lib\unittest\case.py", line 680, in fail
    raise self.failureException(msg)
AssertionError: {'code': 1003, 'msg': '用户名或者密码错误'} != {'code': 9999, 'msg': '登录成功'}
- {'code': 1003, 'msg': '用户名或者密码错误'}
+ {'code': 9999, 'msg': '登录成功'}
2021-12-07 15:25:12,057-[test_login.py - 42]-INFO:测试编号3,测试用例标题登录接口用户名为空的场景,执行成功!
2021-12-07 15:25:12,113-[test_login.py - 36]-ERROR:测试编号4,测试用例标题登录接口密码输入错误的场景,执行失败!实际结果{'code': 9999, 'msg': '登录成功'}
2021-12-07 15:25:12,114-[test_login.py - 37]-ERROR:{'code': 1003, 'msg': '用户名或者密码错误'} != {'code': 9999, 'msg': '登录成功'}
- {'code': 1003, 'msg': '用户名或者密码错误'}
+ {'code': 9999, 'msg': '登录成功'}
Traceback (most recent call last):
  File "D:\PythonWorkSpace\day16\homework\test_login.py", line 33, in test_login
    self.assertEqual(eval(case.expect), res_body)  # assert 断言的意思，Equal是相等的意思
  File "D:\python\PyCharm Community Edition 2021.2.3\plugins\python-ce\helpers\pycharm\teamcity\diff_tools.py", line 32, in _patched_equals
    old(self, first, second, msg)
  File "C:\Program Files\Python37\lib\unittest\case.py", line 839, in assertEqual
    assertion_func(first, second, msg=msg)
  File "C:\Program Files\Python37\lib\unittest\case.py", line 1138, in assertDictEqual
    self.fail(self._formatMessage(msg, standardMsg))
  File "C:\Program Files\Python37\lib\unittest\case.py", line 680, in fail
    raise self.failureException(msg)
AssertionError: {'code': 1003, 'msg': '用户名或者密码错误'} != {'code': 9999, 'msg': '登录成功'}
- {'code': 1003, 'msg': '用户名或者密码错误'}
+ {'code': 9999, 'msg': '登录成功'}
2021-12-07 15:25:12,164-[test_login.py - 42]-INFO:测试编号5,测试用例标题登录接口密码为空的场景,执行成功!
2021-12-07 15:26:31,279-[log_utils.py - 46]-WARNING:waring级别以上的日志信息
2021-12-07 15:26:31,279-[log_utils.py - 47]-ERROR:error级别以上的日志信息
2021-12-07 15:26:31,466-[test_login.py - 36]-ERROR:测试编号2,测试用例标题登录接口输入错误用户名的场景,执行失败!实际结果{'code': 9999, 'msg': '登录成功'}
2021-12-07 15:26:31,467-[test_login.py - 37]-ERROR:{'code': 1003, 'msg': '用户名或者密码错误'} != {'code': 9999, 'msg': '登录成功'}
- {'code': 1003, 'msg': '用户名或者密码错误'}
+ {'code': 9999, 'msg': '登录成功'}
Traceback (most recent call last):
  File "D:\PythonWorkSpace\day16\homework\test_login.py", line 33, in test_login
    self.assertEqual(eval(case.expect), res_body)  # assert 断言的意思，Equal是相等的意思
  File "D:\python\PyCharm Community Edition 2021.2.3\plugins\python-ce\helpers\pycharm\teamcity\diff_tools.py", line 32, in _patched_equals
    old(self, first, second, msg)
  File "C:\Program Files\Python37\lib\unittest\case.py", line 839, in assertEqual
    assertion_func(first, second, msg=msg)
  File "C:\Program Files\Python37\lib\unittest\case.py", line 1138, in assertDictEqual
    self.fail(self._formatMessage(msg, standardMsg))
  File "C:\Program Files\Python37\lib\unittest\case.py", line 680, in fail
    raise self.failureException(msg)
AssertionError: {'code': 1003, 'msg': '用户名或者密码错误'} != {'code': 9999, 'msg': '登录成功'}
- {'code': 1003, 'msg': '用户名或者密码错误'}
+ {'code': 9999, 'msg': '登录成功'}
2021-12-07 15:26:31,575-[test_login.py - 42]-INFO:测试编号3,测试用例标题登录接口用户名为空的场景,执行成功!
2021-12-07 15:26:31,644-[test_login.py - 36]-ERROR:测试编号4,测试用例标题登录接口密码输入错误的场景,执行失败!实际结果{'code': 9999, 'msg': '登录成功'}
2021-12-07 15:26:31,644-[test_login.py - 37]-ERROR:{'code': 1003, 'msg': '用户名或者密码错误'} != {'code': 9999, 'msg': '登录成功'}
- {'code': 1003, 'msg': '用户名或者密码错误'}
+ {'code': 9999, 'msg': '登录成功'}
Traceback (most recent call last):
  File "D:\PythonWorkSpace\day16\homework\test_login.py", line 33, in test_login
    self.assertEqual(eval(case.expect), res_body)  # assert 断言的意思，Equal是相等的意思
  File "D:\python\PyCharm Community Edition 2021.2.3\plugins\python-ce\helpers\pycharm\teamcity\diff_tools.py", line 32, in _patched_equals
    old(self, first, second, msg)
  File "C:\Program Files\Python37\lib\unittest\case.py", line 839, in assertEqual
    assertion_func(first, second, msg=msg)
  File "C:\Program Files\Python37\lib\unittest\case.py", line 1138, in assertDictEqual
    self.fail(self._formatMessage(msg, standardMsg))
  File "C:\Program Files\Python37\lib\unittest\case.py", line 680, in fail
    raise self.failureException(msg)
AssertionError: {'code': 1003, 'msg': '用户名或者密码错误'} != {'code': 9999, 'msg': '登录成功'}
- {'code': 1003, 'msg': '用户名或者密码错误'}
+ {'code': 9999, 'msg': '登录成功'}
2021-12-07 15:26:31,704-[test_login.py - 42]-INFO:测试编号5,测试用例标题登录接口密码为空的场景,执行成功!
2021-12-07 15:27:09,588-[log_utils.py - 46]-WARNING:waring级别以上的日志信息
2021-12-07 15:27:09,588-[log_utils.py - 47]-ERROR:error级别以上的日志信息
2021-12-07 15:27:09,716-[test_login.py - 36]-ERROR:测试编号2,测试用例标题登录接口输入错误用户名的场景,执行失败!实际结果{'code': 9999, 'msg': '登录成功'}
2021-12-07 15:27:09,716-[test_login.py - 37]-ERROR:{'code': 1003, 'msg': '用户名或者密码错误'} != {'code': 9999, 'msg': '登录成功'}
- {'code': 1003, 'msg': '用户名或者密码错误'}
+ {'code': 9999, 'msg': '登录成功'}
Traceback (most recent call last):
  File "D:\PythonWorkSpace\day16\homework\test_login.py", line 33, in test_login
    self.assertEqual(eval(case.expect), res_body)  # assert 断言的意思，Equal是相等的意思
  File "D:\python\PyCharm Community Edition 2021.2.3\plugins\python-ce\helpers\pycharm\teamcity\diff_tools.py", line 32, in _patched_equals
    old(self, first, second, msg)
  File "C:\Program Files\Python37\lib\unittest\case.py", line 839, in assertEqual
    assertion_func(first, second, msg=msg)
  File "C:\Program Files\Python37\lib\unittest\case.py", line 1138, in assertDictEqual
    self.fail(self._formatMessage(msg, standardMsg))
  File "C:\Program Files\Python37\lib\unittest\case.py", line 680, in fail
    raise self.failureException(msg)
AssertionError: {'code': 1003, 'msg': '用户名或者密码错误'} != {'code': 9999, 'msg': '登录成功'}
- {'code': 1003, 'msg': '用户名或者密码错误'}
+ {'code': 9999, 'msg': '登录成功'}
2021-12-07 15:27:09,798-[test_login.py - 42]-INFO:测试编号3,测试用例标题登录接口用户名为空的场景,执行成功!
2021-12-07 15:27:09,852-[test_login.py - 36]-ERROR:测试编号4,测试用例标题登录接口密码输入错误的场景,执行失败!实际结果{'code': 9999, 'msg': '登录成功'}
2021-12-07 15:27:09,852-[test_login.py - 37]-ERROR:{'code': 1003, 'msg': '用户名或者密码错误'} != {'code': 9999, 'msg': '登录成功'}
- {'code': 1003, 'msg': '用户名或者密码错误'}
+ {'code': 9999, 'msg': '登录成功'}
Traceback (most recent call last):
  File "D:\PythonWorkSpace\day16\homework\test_login.py", line 33, in test_login
    self.assertEqual(eval(case.expect), res_body)  # assert 断言的意思，Equal是相等的意思
  File "D:\python\PyCharm Community Edition 2021.2.3\plugins\python-ce\helpers\pycharm\teamcity\diff_tools.py", line 32, in _patched_equals
    old(self, first, second, msg)
  File "C:\Program Files\Python37\lib\unittest\case.py", line 839, in assertEqual
    assertion_func(first, second, msg=msg)
  File "C:\Program Files\Python37\lib\unittest\case.py", line 1138, in assertDictEqual
    self.fail(self._formatMessage(msg, standardMsg))
  File "C:\Program Files\Python37\lib\unittest\case.py", line 680, in fail
    raise self.failureException(msg)
AssertionError: {'code': 1003, 'msg': '用户名或者密码错误'} != {'code': 9999, 'msg': '登录成功'}
- {'code': 1003, 'msg': '用户名或者密码错误'}
+ {'code': 9999, 'msg': '登录成功'}
2021-12-07 15:27:09,901-[test_login.py - 42]-INFO:测试编号5,测试用例标题登录接口密码为空的场景,执行成功!
2021-12-07 15:27:32,412-[log_utils.py - 46]-WARNING:waring级别以上的日志信息
2021-12-07 15:27:32,412-[log_utils.py - 47]-ERROR:error级别以上的日志信息
2021-12-07 15:27:32,533-[test_login.py - 42]-INFO:测试编号1,测试用例标题登录接口主流程,执行成功!
2021-12-07 15:27:32,597-[test_login.py - 36]-ERROR:测试编号2,测试用例标题登录接口输入错误用户名的场景,执行失败!实际结果{'code': 9999, 'msg': '登录成功'}
2021-12-07 15:27:32,597-[test_login.py - 37]-ERROR:{'code': 1003, 'msg': '用户名或者密码错误'} != {'code': 9999, 'msg': '登录成功'}
- {'code': 1003, 'msg': '用户名或者密码错误'}
+ {'code': 9999, 'msg': '登录成功'}
Traceback (most recent call last):
  File "D:\PythonWorkSpace\day16\homework\test_login.py", line 33, in test_login
    self.assertEqual(eval(case.expect), res_body)  # assert 断言的意思，Equal是相等的意思
  File "D:\python\PyCharm Community Edition 2021.2.3\plugins\python-ce\helpers\pycharm\teamcity\diff_tools.py", line 32, in _patched_equals
    old(self, first, second, msg)
  File "C:\Program Files\Python37\lib\unittest\case.py", line 839, in assertEqual
    assertion_func(first, second, msg=msg)
  File "C:\Program Files\Python37\lib\unittest\case.py", line 1138, in assertDictEqual
    self.fail(self._formatMessage(msg, standardMsg))
  File "C:\Program Files\Python37\lib\unittest\case.py", line 680, in fail
    raise self.failureException(msg)
AssertionError: {'code': 1003, 'msg': '用户名或者密码错误'} != {'code': 9999, 'msg': '登录成功'}
- {'code': 1003, 'msg': '用户名或者密码错误'}
+ {'code': 9999, 'msg': '登录成功'}
2021-12-07 15:27:32,644-[test_login.py - 42]-INFO:测试编号3,测试用例标题登录接口用户名为空的场景,执行成功!
2021-12-07 15:27:32,695-[test_login.py - 36]-ERROR:测试编号4,测试用例标题登录接口密码输入错误的场景,执行失败!实际结果{'code': 9999, 'msg': '登录成功'}
2021-12-07 15:27:32,695-[test_login.py - 37]-ERROR:{'code': 1003, 'msg': '用户名或者密码错误'} != {'code': 9999, 'msg': '登录成功'}
- {'code': 1003, 'msg': '用户名或者密码错误'}
+ {'code': 9999, 'msg': '登录成功'}
Traceback (most recent call last):
  File "D:\PythonWorkSpace\day16\homework\test_login.py", line 33, in test_login
    self.assertEqual(eval(case.expect), res_body)  # assert 断言的意思，Equal是相等的意思
  File "D:\python\PyCharm Community Edition 2021.2.3\plugins\python-ce\helpers\pycharm\teamcity\diff_tools.py", line 32, in _patched_equals
    old(self, first, second, msg)
  File "C:\Program Files\Python37\lib\unittest\case.py", line 839, in assertEqual
    assertion_func(first, second, msg=msg)
  File "C:\Program Files\Python37\lib\unittest\case.py", line 1138, in assertDictEqual
    self.fail(self._formatMessage(msg, standardMsg))
  File "C:\Program Files\Python37\lib\unittest\case.py", line 680, in fail
    raise self.failureException(msg)
AssertionError: {'code': 1003, 'msg': '用户名或者密码错误'} != {'code': 9999, 'msg': '登录成功'}
- {'code': 1003, 'msg': '用户名或者密码错误'}
+ {'code': 9999, 'msg': '登录成功'}
2021-12-07 15:27:32,743-[test_login.py - 42]-INFO:测试编号5,测试用例标题登录接口密码为空的场景,执行成功!
2021-12-07 15:30:24,444-[log_utils.py - 46]-WARNING:waring级别以上的日志信息
2021-12-07 15:30:24,444-[log_utils.py - 47]-ERROR:error级别以上的日志信息
2021-12-07 15:30:24,618-[test_login.py - 42]-INFO:测试编号3,测试用例标题登录接口用户名为空的场景,执行成功!
2021-12-07 15:30:24,720-[test_login.py - 42]-INFO:测试编号5,测试用例标题登录接口密码为空的场景,执行成功!
2021-12-07 15:30:45,284-[log_utils.py - 46]-WARNING:waring级别以上的日志信息
2021-12-07 15:30:45,284-[log_utils.py - 47]-ERROR:error级别以上的日志信息
2021-12-07 15:30:45,461-[test_login.py - 42]-INFO:测试编号3,测试用例标题登录接口用户名为空的场景,执行成功!
2021-12-07 15:30:45,541-[test_login.py - 42]-INFO:测试编号5,测试用例标题登录接口密码为空的场景,执行成功!
2021-12-07 15:31:06,082-[log_utils.py - 46]-WARNING:waring级别以上的日志信息
2021-12-07 15:31:06,082-[log_utils.py - 47]-ERROR:error级别以上的日志信息
2021-12-07 15:32:07,842-[test_login.py - 42]-INFO:测试编号3,测试用例标题登录接口用户名为空的场景,执行成功!
2021-12-07 15:32:07,919-[test_login.py - 42]-INFO:测试编号5,测试用例标题登录接口密码为空的场景,执行成功!
2021-12-07 15:32:11,747-[log_utils.py - 46]-WARNING:waring级别以上的日志信息
2021-12-07 15:32:11,747-[log_utils.py - 47]-ERROR:error级别以上的日志信息
2021-12-07 15:32:11,897-[test_login.py - 42]-INFO:测试编号3,测试用例标题登录接口用户名为空的场景,执行成功!
2021-12-07 15:32:11,984-[test_login.py - 42]-INFO:测试编号5,测试用例标题登录接口密码为空的场景,执行成功!
2021-12-07 15:34:44,523-[log_utils.py - 46]-WARNING:waring级别以上的日志信息
2021-12-07 15:34:44,523-[log_utils.py - 47]-ERROR:error级别以上的日志信息
2021-12-07 15:34:44,644-[test_login.py - 42]-INFO:测试编号1,测试用例标题登录接口主流程,执行成功!
2021-12-07 15:34:44,722-[test_login.py - 42]-INFO:测试编号2,测试用例标题登录接口输入错误用户名的场景,执行成功!
2021-12-07 15:34:44,784-[test_login.py - 42]-INFO:测试编号3,测试用例标题登录接口用户名为空的场景,执行成功!
2021-12-07 15:34:44,843-[test_login.py - 42]-INFO:测试编号4,测试用例标题登录接口密码输入错误的场景,执行成功!
2021-12-07 15:34:44,898-[test_login.py - 42]-INFO:测试编号5,测试用例标题登录接口密码为空的场景,执行成功!
2021-12-07 15:37:23,814-[log_utils.py - 46]-WARNING:waring级别以上的日志信息
2021-12-07 15:37:23,814-[log_utils.py - 47]-ERROR:error级别以上的日志信息
2021-12-07 15:37:55,649-[log_utils.py - 46]-WARNING:waring级别以上的日志信息
2021-12-07 15:37:55,649-[log_utils.py - 47]-ERROR:error级别以上的日志信息
2021-12-07 15:37:55,777-[test_login.py - 42]-INFO:测试编号1,测试用例标题登录接口主流程,执行成功!
2021-12-07 15:37:55,846-[test_login.py - 42]-INFO:测试编号2,测试用例标题登录接口输入错误用户名的场景,执行成功!
2021-12-07 15:37:55,890-[test_login.py - 42]-INFO:测试编号3,测试用例标题登录接口用户名为空的场景,执行成功!
2021-12-07 15:37:55,940-[test_login.py - 42]-INFO:测试编号4,测试用例标题登录接口密码输入错误的场景,执行成功!
2021-12-07 15:37:55,984-[test_login.py - 42]-INFO:测试编号5,测试用例标题登录接口密码为空的场景,执行成功!
2021-12-07 15:38:56,854-[log_utils.py - 46]-WARNING:waring级别以上的日志信息
2021-12-07 15:38:56,854-[log_utils.py - 47]-ERROR:error级别以上的日志信息
2021-12-07 15:38:57,040-[test_login.py - 42]-INFO:测试编号1,测试用例标题登录接口主流程,执行成功!
2021-12-07 15:38:57,107-[test_login.py - 42]-INFO:测试编号2,测试用例标题登录接口输入错误用户名的场景,执行成功!
2021-12-07 15:38:57,152-[test_login.py - 42]-INFO:测试编号3,测试用例标题登录接口用户名为空的场景,执行成功!
2021-12-07 15:38:57,201-[test_login.py - 42]-INFO:测试编号4,测试用例标题登录接口密码输入错误的场景,执行成功!
2021-12-07 15:38:57,245-[test_login.py - 42]-INFO:测试编号5,测试用例标题登录接口密码为空的场景,执行成功!
2021-12-07 15:40:57,986-[log_utils.py - 46]-WARNING:waring级别以上的日志信息
2021-12-07 15:40:57,986-[log_utils.py - 47]-ERROR:error级别以上的日志信息
2021-12-07 15:40:58,630-[test_login.py - 42]-INFO:测试编号1,测试用例标题登录接口主流程,执行成功!
2021-12-07 15:40:58,688-[test_login.py - 42]-INFO:测试编号2,测试用例标题登录接口输入错误用户名的场景,执行成功!
2021-12-07 15:40:58,750-[test_login.py - 42]-INFO:测试编号3,测试用例标题登录接口用户名为空的场景,执行成功!
2021-12-07 15:40:58,797-[test_login.py - 42]-INFO:测试编号4,测试用例标题登录接口密码输入错误的场景,执行成功!
2021-12-07 15:40:58,846-[test_login.py - 42]-INFO:测试编号5,测试用例标题登录接口密码为空的场景,执行成功!
2021-12-07 15:44:16,903-[log_utils.py - 46]-WARNING:waring级别以上的日志信息
2021-12-07 15:44:16,903-[log_utils.py - 47]-ERROR:error级别以上的日志信息
2021-12-07 15:44:17,040-[test_login.py - 42]-INFO:测试编号1,测试用例标题登录接口主流程,执行成功!
2021-12-07 15:44:17,097-[test_login.py - 42]-INFO:测试编号2,测试用例标题登录接口输入错误用户名的场景,执行成功!
2021-12-07 15:44:17,153-[test_login.py - 42]-INFO:测试编号3,测试用例标题登录接口用户名为空的场景,执行成功!
2021-12-07 15:44:17,200-[test_login.py - 42]-INFO:测试编号4,测试用例标题登录接口密码输入错误的场景,执行成功!
2021-12-07 15:44:17,246-[test_login.py - 42]-INFO:测试编号5,测试用例标题登录接口密码为空的场景,执行成功!
2021-12-07 16:15:25,987-[log_utils.py - 46]-WARNING:waring级别以上的日志信息
2021-12-07 16:15:25,987-[log_utils.py - 47]-ERROR:error级别以上的日志信息
2021-12-07 16:15:26,661-[test_register.py - 37]-ERROR:测试编号1,测试用例标题注册主流程,执行失败!实际结果{'code': 1010, 'msg': '用户名已经被注册'}
2021-12-07 16:15:26,661-[test_register.py - 38]-ERROR:{'code': 9999, 'msg': '注册成功'} != {'code': 1010, 'msg': '用户名已经被注册'}
- {'code': 9999, 'msg': '注册成功'}
+ {'code': 1010, 'msg': '用户名已经被注册'}
Traceback (most recent call last):
  File "D:\PythonWorkSpace\day16\homework\test_register.py", line 34, in test_register
    self.assertEqual(eval(case.expect), res_body)  # assert 断言的意思，Equal是相等的意思
  File "D:\python\PyCharm Community Edition 2021.2.3\plugins\python-ce\helpers\pycharm\teamcity\diff_tools.py", line 32, in _patched_equals
    old(self, first, second, msg)
  File "C:\Program Files\Python37\lib\unittest\case.py", line 839, in assertEqual
    assertion_func(first, second, msg=msg)
  File "C:\Program Files\Python37\lib\unittest\case.py", line 1138, in assertDictEqual
    self.fail(self._formatMessage(msg, standardMsg))
  File "C:\Program Files\Python37\lib\unittest\case.py", line 680, in fail
    raise self.failureException(msg)
AssertionError: {'code': 9999, 'msg': '注册成功'} != {'code': 1010, 'msg': '用户名已经被注册'}
- {'code': 9999, 'msg': '注册成功'}
+ {'code': 1010, 'msg': '用户名已经被注册'}
2021-12-07 16:15:44,405-[log_utils.py - 46]-WARNING:waring级别以上的日志信息
2021-12-07 16:15:44,405-[log_utils.py - 47]-ERROR:error级别以上的日志信息
2021-12-07 16:15:44,543-[test_register.py - 37]-ERROR:测试编号1,测试用例标题注册主流程,执行失败!实际结果{'code': 1010, 'msg': '用户名已经被注册'}
2021-12-07 16:15:44,543-[test_register.py - 38]-ERROR:{'code': 9999, 'msg': '注册成功'} != {'code': 1010, 'msg': '用户名已经被注册'}
- {'code': 9999, 'msg': '注册成功'}
+ {'code': 1010, 'msg': '用户名已经被注册'}
Traceback (most recent call last):
  File "D:\PythonWorkSpace\day16\homework\test_register.py", line 34, in test_register
    self.assertEqual(eval(case.expect), res_body)  # assert 断言的意思，Equal是相等的意思
  File "D:\python\PyCharm Community Edition 2021.2.3\plugins\python-ce\helpers\pycharm\teamcity\diff_tools.py", line 32, in _patched_equals
    old(self, first, second, msg)
  File "C:\Program Files\Python37\lib\unittest\case.py", line 839, in assertEqual
    assertion_func(first, second, msg=msg)
  File "C:\Program Files\Python37\lib\unittest\case.py", line 1138, in assertDictEqual
    self.fail(self._formatMessage(msg, standardMsg))
  File "C:\Program Files\Python37\lib\unittest\case.py", line 680, in fail
    raise self.failureException(msg)
AssertionError: {'code': 9999, 'msg': '注册成功'} != {'code': 1010, 'msg': '用户名已经被注册'}
- {'code': 9999, 'msg': '注册成功'}
+ {'code': 1010, 'msg': '用户名已经被注册'}
2021-12-07 16:27:18,170-[log_utils.py - 46]-WARNING:waring级别以上的日志信息
2021-12-07 16:27:18,170-[log_utils.py - 47]-ERROR:error级别以上的日志信息
2021-12-07 16:27:18,286-[test_register.py - 39]-ERROR:测试编号1,测试用例标题注册主流程,执行失败!实际结果{'code': 1010, 'msg': '用户名已经被注册'}
2021-12-07 16:27:18,287-[test_register.py - 40]-ERROR:{'code': 9999, 'msg': '注册成功'} != {'code': 1010, 'msg': '用户名已经被注册'}
- {'code': 9999, 'msg': '注册成功'}
+ {'code': 1010, 'msg': '用户名已经被注册'}
Traceback (most recent call last):
  File "D:\PythonWorkSpace\day16\homework\test_register.py", line 36, in test_register
    self.assertEqual(eval(case.expect), res_body)  # assert 断言的意思，Equal是相等的意思
  File "D:\python\PyCharm Community Edition 2021.2.3\plugins\python-ce\helpers\pycharm\teamcity\diff_tools.py", line 32, in _patched_equals
    old(self, first, second, msg)
  File "C:\Program Files\Python37\lib\unittest\case.py", line 839, in assertEqual
    assertion_func(first, second, msg=msg)
  File "C:\Program Files\Python37\lib\unittest\case.py", line 1138, in assertDictEqual
    self.fail(self._formatMessage(msg, standardMsg))
  File "C:\Program Files\Python37\lib\unittest\case.py", line 680, in fail
    raise self.failureException(msg)
AssertionError: {'code': 9999, 'msg': '注册成功'} != {'code': 1010, 'msg': '用户名已经被注册'}
- {'code': 9999, 'msg': '注册成功'}
+ {'code': 1010, 'msg': '用户名已经被注册'}
2021-12-07 16:28:01,085-[log_utils.py - 46]-WARNING:waring级别以上的日志信息
2021-12-07 16:28:01,085-[log_utils.py - 47]-ERROR:error级别以上的日志信息
2021-12-07 16:28:01,221-[test_register.py - 39]-ERROR:测试编号1,测试用例标题注册主流程,执行失败!实际结果{'code': 1010, 'msg': '用户名已经被注册'}
2021-12-07 16:28:01,221-[test_register.py - 40]-ERROR:{'code': 9999, 'msg': '注册成功'} != {'code': 1010, 'msg': '用户名已经被注册'}
- {'code': 9999, 'msg': '注册成功'}
+ {'code': 1010, 'msg': '用户名已经被注册'}
Traceback (most recent call last):
  File "D:\PythonWorkSpace\day16\homework\test_register.py", line 36, in test_register
    self.assertEqual(eval(case.expect), res_body)  # assert 断言的意思，Equal是相等的意思
  File "D:\python\PyCharm Community Edition 2021.2.3\plugins\python-ce\helpers\pycharm\teamcity\diff_tools.py", line 32, in _patched_equals
    old(self, first, second, msg)
  File "C:\Program Files\Python37\lib\unittest\case.py", line 839, in assertEqual
    assertion_func(first, second, msg=msg)
  File "C:\Program Files\Python37\lib\unittest\case.py", line 1138, in assertDictEqual
    self.fail(self._formatMessage(msg, standardMsg))
  File "C:\Program Files\Python37\lib\unittest\case.py", line 680, in fail
    raise self.failureException(msg)
AssertionError: {'code': 9999, 'msg': '注册成功'} != {'code': 1010, 'msg': '用户名已经被注册'}
- {'code': 9999, 'msg': '注册成功'}
+ {'code': 1010, 'msg': '用户名已经被注册'}
2021-12-07 16:28:49,429-[log_utils.py - 46]-WARNING:waring级别以上的日志信息
2021-12-07 16:28:49,429-[log_utils.py - 47]-ERROR:error级别以上的日志信息
2021-12-07 16:28:49,583-[test_register.py - 39]-ERROR:测试编号1,测试用例标题注册主流程,执行失败!实际结果{'code': 1010, 'msg': '用户名已经被注册'}
2021-12-07 16:28:49,583-[test_register.py - 40]-ERROR:{'code': 9999, 'msg': '注册成功'} != {'code': 1010, 'msg': '用户名已经被注册'}
- {'code': 9999, 'msg': '注册成功'}
+ {'code': 1010, 'msg': '用户名已经被注册'}
Traceback (most recent call last):
  File "D:\PythonWorkSpace\day16\homework\test_register.py", line 36, in test_register
    self.assertEqual(eval(case.expect), res_body)  # assert 断言的意思，Equal是相等的意思
  File "D:\python\PyCharm Community Edition 2021.2.3\plugins\python-ce\helpers\pycharm\teamcity\diff_tools.py", line 32, in _patched_equals
    old(self, first, second, msg)
  File "C:\Program Files\Python37\lib\unittest\case.py", line 839, in assertEqual
    assertion_func(first, second, msg=msg)
  File "C:\Program Files\Python37\lib\unittest\case.py", line 1138, in assertDictEqual
    self.fail(self._formatMessage(msg, standardMsg))
  File "C:\Program Files\Python37\lib\unittest\case.py", line 680, in fail
    raise self.failureException(msg)
AssertionError: {'code': 9999, 'msg': '注册成功'} != {'code': 1010, 'msg': '用户名已经被注册'}
- {'code': 9999, 'msg': '注册成功'}
+ {'code': 1010, 'msg': '用户名已经被注册'}
2021-12-07 16:33:31,904-[log_utils.py - 46]-WARNING:waring级别以上的日志信息
2021-12-07 16:33:31,904-[log_utils.py - 47]-ERROR:error级别以上的日志信息
2021-12-07 16:34:05,169-[log_utils.py - 46]-WARNING:waring级别以上的日志信息
2021-12-07 16:34:05,169-[log_utils.py - 47]-ERROR:error级别以上的日志信息
2021-12-07 16:34:24,199-[log_utils.py - 46]-WARNING:waring级别以上的日志信息
2021-12-07 16:34:24,199-[log_utils.py - 47]-ERROR:error级别以上的日志信息
2021-12-07 16:34:40,948-[log_utils.py - 46]-WARNING:waring级别以上的日志信息
2021-12-07 16:34:40,948-[log_utils.py - 47]-ERROR:error级别以上的日志信息
2021-12-07 16:41:41,752-[log_utils.py - 46]-WARNING:waring级别以上的日志信息
2021-12-07 16:41:41,752-[log_utils.py - 47]-ERROR:error级别以上的日志信息
2021-12-07 17:10:04,747-[log_utils.py - 46]-WARNING:waring级别以上的日志信息
2021-12-07 17:10:04,747-[log_utils.py - 47]-ERROR:error级别以上的日志信息
2021-12-07 17:10:46,599-[log_utils.py - 46]-WARNING:waring级别以上的日志信息
2021-12-07 17:10:46,599-[log_utils.py - 47]-ERROR:error级别以上的日志信息
2021-12-07 17:10:46,754-[test_register.py - 53]-ERROR:测试编号｛｝，测试用例标题｛｝，执行失败!实际结果｛｝
2021-12-07 17:10:46,754-[test_register.py - 54]-ERROR:{'code': 9999, 'msg': '注册成功'} != {'code': 1008, 'msg': '邮箱不能为空'}
- {'code': 9999, 'msg': '注册成功'}
+ {'code': 1008, 'msg': '邮箱不能为空'}
Traceback (most recent call last):
  File "D:\PythonWorkSpace\day16\homework\test_register.py", line 50, in test_register
    self.assertEqual(eval(case.expect), res_body)
  File "D:\python\PyCharm Community Edition 2021.2.3\plugins\python-ce\helpers\pycharm\teamcity\diff_tools.py", line 32, in _patched_equals
    old(self, first, second, msg)
  File "C:\Program Files\Python37\lib\unittest\case.py", line 839, in assertEqual
    assertion_func(first, second, msg=msg)
  File "C:\Program Files\Python37\lib\unittest\case.py", line 1138, in assertDictEqual
    self.fail(self._formatMessage(msg, standardMsg))
  File "C:\Program Files\Python37\lib\unittest\case.py", line 680, in fail
    raise self.failureException(msg)
AssertionError: {'code': 9999, 'msg': '注册成功'} != {'code': 1008, 'msg': '邮箱不能为空'}
- {'code': 9999, 'msg': '注册成功'}
+ {'code': 1008, 'msg': '邮箱不能为空'}
2021-12-07 17:10:46,831-[test_register.py - 58]-ERROR:测试编号｛｝，测试用例标题｛｝，执行成功!
2021-12-07 17:10:46,895-[test_register.py - 53]-ERROR:测试编号｛｝，测试用例标题｛｝，执行失败!实际结果｛｝
2021-12-07 17:10:46,895-[test_register.py - 54]-ERROR:{'code': 1002, 'msg': '密码不能为空'} != {'code': 1001, 'msg': '登录名不能为空'}
- {'code': 1002, 'msg': '密码不能为空'}
?             ^          ^^

+ {'code': 1001, 'msg': '登录名不能为空'}
?             ^          ^^^
Traceback (most recent call last):
  File "D:\PythonWorkSpace\day16\homework\test_register.py", line 50, in test_register
    self.assertEqual(eval(case.expect), res_body)
  File "D:\python\PyCharm Community Edition 2021.2.3\plugins\python-ce\helpers\pycharm\teamcity\diff_tools.py", line 32, in _patched_equals
    old(self, first, second, msg)
  File "C:\Program Files\Python37\lib\unittest\case.py", line 839, in assertEqual
    assertion_func(first, second, msg=msg)
  File "C:\Program Files\Python37\lib\unittest\case.py", line 1138, in assertDictEqual
    self.fail(self._formatMessage(msg, standardMsg))
  File "C:\Program Files\Python37\lib\unittest\case.py", line 680, in fail
    raise self.failureException(msg)
AssertionError: {'code': 1002, 'msg': '密码不能为空'} != {'code': 1001, 'msg': '登录名不能为空'}
- {'code': 1002, 'msg': '密码不能为空'}
?             ^          ^^

+ {'code': 1001, 'msg': '登录名不能为空'}
?             ^          ^^^

2021-12-07 17:10:46,956-[test_register.py - 53]-ERROR:测试编号｛｝，测试用例标题｛｝，执行失败!实际结果｛｝
2021-12-07 17:10:46,956-[test_register.py - 54]-ERROR:{'code': 1003, 'mag': '确认密码不能为空'} != {'code': 1005, 'msg': '两次密码输入不一致'}
- {'code': 1003, 'mag': '确认密码不能为空'}
?             ^    ^     ^^   ^^^

+ {'code': 1005, 'msg': '两次密码输入不一致'}
?             ^    ^     ^^  ++ ^^
Traceback (most recent call last):
  File "D:\PythonWorkSpace\day16\homework\test_register.py", line 50, in test_register
    self.assertEqual(eval(case.expect), res_body)
  File "D:\python\PyCharm Community Edition 2021.2.3\plugins\python-ce\helpers\pycharm\teamcity\diff_tools.py", line 32, in _patched_equals
    old(self, first, second, msg)
  File "C:\Program Files\Python37\lib\unittest\case.py", line 839, in assertEqual
    assertion_func(first, second, msg=msg)
  File "C:\Program Files\Python37\lib\unittest\case.py", line 1138, in assertDictEqual
    self.fail(self._formatMessage(msg, standardMsg))
  File "C:\Program Files\Python37\lib\unittest\case.py", line 680, in fail
    raise self.failureException(msg)
AssertionError: {'code': 1003, 'mag': '确认密码不能为空'} != {'code': 1005, 'msg': '两次密码输入不一致'}
- {'code': 1003, 'mag': '确认密码不能为空'}
?             ^    ^     ^^   ^^^

+ {'code': 1005, 'msg': '两次密码输入不一致'}
?             ^    ^     ^^  ++ ^^

2021-12-07 17:10:47,025-[test_register.py - 58]-ERROR:测试编号｛｝，测试用例标题｛｝，执行成功!
2021-12-07 17:13:02,190-[log_utils.py - 46]-WARNING:waring级别以上的日志信息
2021-12-07 17:13:02,190-[log_utils.py - 47]-ERROR:error级别以上的日志信息
2021-12-07 17:13:02,332-[test_register.py - 58]-ERROR:测试编号｛｝，测试用例标题｛｝，执行成功!
2021-12-07 17:13:02,400-[test_register.py - 58]-ERROR:测试编号｛｝，测试用例标题｛｝，执行成功!
2021-12-07 17:13:02,457-[test_register.py - 58]-ERROR:测试编号｛｝，测试用例标题｛｝，执行成功!
2021-12-07 17:13:02,522-[test_register.py - 53]-ERROR:测试编号｛｝，测试用例标题｛｝，执行失败!实际结果｛｝
2021-12-07 17:13:02,522-[test_register.py - 54]-ERROR:{'code': 1003, 'mag': '确认密码不能为空'} != {'code': 1005, 'msg': '两次密码输入不一致'}
- {'code': 1003, 'mag': '确认密码不能为空'}
?             ^    ^     ^^   ^^^

+ {'code': 1005, 'msg': '两次密码输入不一致'}
?             ^    ^     ^^  ++ ^^
Traceback (most recent call last):
  File "D:\PythonWorkSpace\day16\homework\test_register.py", line 50, in test_register
    self.assertEqual(eval(case.expect), res_body)
  File "D:\python\PyCharm Community Edition 2021.2.3\plugins\python-ce\helpers\pycharm\teamcity\diff_tools.py", line 32, in _patched_equals
    old(self, first, second, msg)
  File "C:\Program Files\Python37\lib\unittest\case.py", line 839, in assertEqual
    assertion_func(first, second, msg=msg)
  File "C:\Program Files\Python37\lib\unittest\case.py", line 1138, in assertDictEqual
    self.fail(self._formatMessage(msg, standardMsg))
  File "C:\Program Files\Python37\lib\unittest\case.py", line 680, in fail
    raise self.failureException(msg)
AssertionError: {'code': 1003, 'mag': '确认密码不能为空'} != {'code': 1005, 'msg': '两次密码输入不一致'}
- {'code': 1003, 'mag': '确认密码不能为空'}
?             ^    ^     ^^   ^^^

+ {'code': 1005, 'msg': '两次密码输入不一致'}
?             ^    ^     ^^  ++ ^^

2021-12-07 17:13:02,579-[test_register.py - 58]-ERROR:测试编号｛｝，测试用例标题｛｝，执行成功!
2021-12-07 17:15:47,131-[log_utils.py - 46]-WARNING:waring级别以上的日志信息
2021-12-07 17:15:47,132-[log_utils.py - 47]-ERROR:error级别以上的日志信息
2021-12-07 17:15:47,283-[test_register.py - 58]-ERROR:测试编号｛｝，测试用例标题｛｝，执行成功!
2021-12-07 17:15:47,353-[test_register.py - 58]-ERROR:测试编号｛｝，测试用例标题｛｝，执行成功!
2021-12-07 17:15:47,408-[test_register.py - 58]-ERROR:测试编号｛｝，测试用例标题｛｝，执行成功!
2021-12-07 17:15:47,464-[test_register.py - 53]-ERROR:测试编号｛｝，测试用例标题｛｝，执行失败!实际结果｛｝
2021-12-07 17:15:47,465-[test_register.py - 54]-ERROR:{'code': 1003, 'mag': '确认密码不能为空'} != {'code': 1005, 'msg': '两次密码输入不一致'}
- {'code': 1003, 'mag': '确认密码不能为空'}
?             ^    ^     ^^   ^^^

+ {'code': 1005, 'msg': '两次密码输入不一致'}
?             ^    ^     ^^  ++ ^^
Traceback (most recent call last):
  File "D:\PythonWorkSpace\day16\homework\test_register.py", line 50, in test_register
    self.assertEqual(eval(case.expect), res_body)
  File "D:\python\PyCharm Community Edition 2021.2.3\plugins\python-ce\helpers\pycharm\teamcity\diff_tools.py", line 32, in _patched_equals
    old(self, first, second, msg)
  File "C:\Program Files\Python37\lib\unittest\case.py", line 839, in assertEqual
    assertion_func(first, second, msg=msg)
  File "C:\Program Files\Python37\lib\unittest\case.py", line 1138, in assertDictEqual
    self.fail(self._formatMessage(msg, standardMsg))
  File "C:\Program Files\Python37\lib\unittest\case.py", line 680, in fail
    raise self.failureException(msg)
AssertionError: {'code': 1003, 'mag': '确认密码不能为空'} != {'code': 1005, 'msg': '两次密码输入不一致'}
- {'code': 1003, 'mag': '确认密码不能为空'}
?             ^    ^     ^^   ^^^

+ {'code': 1005, 'msg': '两次密码输入不一致'}
?             ^    ^     ^^  ++ ^^

2021-12-07 17:15:47,520-[test_register.py - 58]-ERROR:测试编号｛｝，测试用例标题｛｝，执行成功!
2021-12-07 17:19:55,543-[log_utils.py - 46]-WARNING:waring级别以上的日志信息
2021-12-07 17:19:55,545-[log_utils.py - 47]-ERROR:error级别以上的日志信息
2021-12-07 17:19:55,823-[test_register.py - 58]-ERROR:测试编号｛｝，测试用例标题｛｝，执行成功!
2021-12-07 17:19:55,927-[test_register.py - 58]-ERROR:测试编号｛｝，测试用例标题｛｝，执行成功!
2021-12-07 17:19:56,008-[test_register.py - 58]-ERROR:测试编号｛｝，测试用例标题｛｝，执行成功!
2021-12-07 17:19:56,103-[test_register.py - 58]-ERROR:测试编号｛｝，测试用例标题｛｝，执行成功!
2021-12-07 17:21:11,718-[log_utils.py - 46]-WARNING:waring级别以上的日志信息
2021-12-07 17:21:11,718-[log_utils.py - 47]-ERROR:error级别以上的日志信息
2021-12-07 17:21:19,192-[log_utils.py - 46]-WARNING:waring级别以上的日志信息
2021-12-07 17:21:19,192-[log_utils.py - 47]-ERROR:error级别以上的日志信息
2021-12-07 17:22:06,667-[log_utils.py - 46]-WARNING:waring级别以上的日志信息
2021-12-07 17:22:06,667-[log_utils.py - 47]-ERROR:error级别以上的日志信息
2021-12-07 17:22:32,898-[log_utils.py - 46]-WARNING:waring级别以上的日志信息
2021-12-07 17:22:32,898-[log_utils.py - 47]-ERROR:error级别以上的日志信息
2021-12-07 17:22:38,970-[log_utils.py - 46]-WARNING:waring级别以上的日志信息
2021-12-07 17:22:38,970-[log_utils.py - 47]-ERROR:error级别以上的日志信息
2021-12-07 17:23:12,037-[log_utils.py - 46]-WARNING:waring级别以上的日志信息
2021-12-07 17:23:12,037-[log_utils.py - 47]-ERROR:error级别以上的日志信息
2021-12-07 17:23:30,616-[log_utils.py - 46]-WARNING:waring级别以上的日志信息
2021-12-07 17:23:30,617-[log_utils.py - 47]-ERROR:error级别以上的日志信息
2021-12-07 17:24:25,839-[log_utils.py - 46]-WARNING:waring级别以上的日志信息
2021-12-07 17:24:25,840-[log_utils.py - 47]-ERROR:error级别以上的日志信息
2021-12-07 17:24:35,821-[log_utils.py - 46]-WARNING:waring级别以上的日志信息
2021-12-07 17:24:35,821-[log_utils.py - 47]-ERROR:error级别以上的日志信息
2021-12-07 17:24:48,205-[log_utils.py - 46]-WARNING:waring级别以上的日志信息
2021-12-07 17:24:48,205-[log_utils.py - 47]-ERROR:error级别以上的日志信息
2021-12-07 17:25:11,426-[log_utils.py - 46]-WARNING:waring级别以上的日志信息
2021-12-07 17:25:11,426-[log_utils.py - 47]-ERROR:error级别以上的日志信息
2021-12-07 17:25:20,004-[log_utils.py - 46]-WARNING:waring级别以上的日志信息
2021-12-07 17:25:20,005-[log_utils.py - 47]-ERROR:error级别以上的日志信息
2021-12-07 17:25:46,980-[log_utils.py - 46]-WARNING:waring级别以上的日志信息
2021-12-07 17:25:46,980-[log_utils.py - 47]-ERROR:error级别以上的日志信息
2021-12-07 17:25:47,278-[test_register.py - 58]-ERROR:测试编号｛｝，测试用例标题｛｝，执行成功!
2021-12-07 17:25:47,373-[test_register.py - 58]-ERROR:测试编号｛｝，测试用例标题｛｝，执行成功!
2021-12-07 17:25:47,449-[test_register.py - 58]-ERROR:测试编号｛｝，测试用例标题｛｝，执行成功!
2021-12-07 17:25:47,512-[test_register.py - 58]-ERROR:测试编号｛｝，测试用例标题｛｝，执行成功!
2021-12-07 17:26:12,964-[log_utils.py - 46]-WARNING:waring级别以上的日志信息
2021-12-07 17:26:12,964-[log_utils.py - 47]-ERROR:error级别以上的日志信息
2021-12-07 17:26:13,695-[test_register.py - 58]-ERROR:测试编号｛｝，测试用例标题｛｝，执行成功!
2021-12-07 17:26:13,760-[test_register.py - 58]-ERROR:测试编号｛｝，测试用例标题｛｝，执行成功!
2021-12-07 17:26:13,824-[test_register.py - 58]-ERROR:测试编号｛｝，测试用例标题｛｝，执行成功!
2021-12-07 17:26:13,913-[test_register.py - 58]-ERROR:测试编号｛｝，测试用例标题｛｝，执行成功!
2021-12-07 17:43:49,187-[log_utils.py - 46]-WARNING:waring级别以上的日志信息
2021-12-07 17:43:49,187-[log_utils.py - 47]-ERROR:error级别以上的日志信息
2021-12-07 17:44:00,501-[log_utils.py - 46]-WARNING:waring级别以上的日志信息
2021-12-07 17:44:00,501-[log_utils.py - 47]-ERROR:error级别以上的日志信息
2021-12-07 17:44:00,719-[test_register.py - 58]-ERROR:测试编号｛｝，测试用例标题｛｝，执行成功!
2021-12-07 17:44:00,797-[test_register.py - 58]-ERROR:测试编号｛｝，测试用例标题｛｝，执行成功!
2021-12-07 17:44:00,856-[test_register.py - 58]-ERROR:测试编号｛｝，测试用例标题｛｝，执行成功!
2021-12-07 17:44:00,913-[test_register.py - 58]-ERROR:测试编号｛｝，测试用例标题｛｝，执行成功!
2021-12-07 17:45:29,142-[log_utils.py - 46]-WARNING:waring级别以上的日志信息
2021-12-07 17:45:29,142-[log_utils.py - 47]-ERROR:error级别以上的日志信息
2021-12-07 17:45:59,009-[log_utils.py - 46]-WARNING:waring级别以上的日志信息
2021-12-07 17:45:59,009-[log_utils.py - 47]-ERROR:error级别以上的日志信息
2021-12-07 17:46:41,156-[log_utils.py - 46]-WARNING:waring级别以上的日志信息
2021-12-07 17:46:41,156-[log_utils.py - 47]-ERROR:error级别以上的日志信息
2021-12-07 17:46:52,553-[log_utils.py - 46]-WARNING:waring级别以上的日志信息
2021-12-07 17:46:52,553-[log_utils.py - 47]-ERROR:error级别以上的日志信息
2021-12-07 17:46:52,696-[test_register.py - 52]-ERROR:测试编号｛｝，测试用例标题｛｝，执行成功!
2021-12-07 17:46:52,784-[test_register.py - 52]-ERROR:测试编号｛｝，测试用例标题｛｝，执行成功!
2021-12-07 17:46:52,872-[test_register.py - 52]-ERROR:测试编号｛｝，测试用例标题｛｝，执行成功!
2021-12-07 17:46:52,960-[test_register.py - 52]-ERROR:测试编号｛｝，测试用例标题｛｝，执行成功!
2021-12-07 17:47:18,602-[log_utils.py - 46]-WARNING:waring级别以上的日志信息
2021-12-07 17:47:18,602-[log_utils.py - 47]-ERROR:error级别以上的日志信息
2021-12-07 17:47:18,757-[test_register.py - 52]-ERROR:测试编号｛｝，测试用例标题｛｝，执行成功!
2021-12-07 17:47:18,838-[test_register.py - 52]-ERROR:测试编号｛｝，测试用例标题｛｝，执行成功!
2021-12-07 17:47:18,895-[test_register.py - 52]-ERROR:测试编号｛｝，测试用例标题｛｝，执行成功!
2021-12-07 17:47:18,966-[test_register.py - 52]-ERROR:测试编号｛｝，测试用例标题｛｝，执行成功!
2021-12-07 17:47:19,032-[test_register.py - 52]-ERROR:测试编号｛｝，测试用例标题｛｝，执行成功!
2021-12-07 17:49:40,989-[log_utils.py - 46]-WARNING:waring级别以上的日志信息
2021-12-07 17:49:40,989-[log_utils.py - 47]-ERROR:error级别以上的日志信息
2021-12-07 17:49:41,139-[test_register.py - 52]-ERROR:测试编号｛｝，测试用例标题｛｝，执行成功!
2021-12-07 17:49:41,211-[test_register.py - 52]-ERROR:测试编号｛｝，测试用例标题｛｝，执行成功!
2021-12-07 17:49:41,264-[test_register.py - 52]-ERROR:测试编号｛｝，测试用例标题｛｝，执行成功!
2021-12-07 17:49:41,319-[test_register.py - 52]-ERROR:测试编号｛｝，测试用例标题｛｝，执行成功!
2021-12-07 17:49:41,377-[test_register.py - 52]-ERROR:测试编号｛｝，测试用例标题｛｝，执行成功!
2021-12-07 17:50:21,082-[log_utils.py - 46]-WARNING:waring级别以上的日志信息
2021-12-07 17:50:21,082-[log_utils.py - 47]-ERROR:error级别以上的日志信息
2021-12-07 17:50:21,268-[test_login.py - 42]-INFO:测试编号1,测试用例标题登录接口主流程,执行成功!
2021-12-07 17:50:21,342-[test_login.py - 42]-INFO:测试编号2,测试用例标题登录接口输入错误用户名的场景,执行成功!
2021-12-07 17:50:21,395-[test_login.py - 42]-INFO:测试编号3,测试用例标题登录接口用户名为空的场景,执行成功!
2021-12-07 17:50:21,447-[test_login.py - 42]-INFO:测试编号4,测试用例标题登录接口密码输入错误的场景,执行成功!
2021-12-07 17:50:21,495-[test_login.py - 42]-INFO:测试编号5,测试用例标题登录接口密码为空的场景,执行成功!
2021-12-07 17:50:21,572-[test_register.py - 52]-ERROR:测试编号｛｝，测试用例标题｛｝，执行成功!
2021-12-07 17:50:21,628-[test_register.py - 52]-ERROR:测试编号｛｝，测试用例标题｛｝，执行成功!
2021-12-07 17:50:21,679-[test_register.py - 52]-ERROR:测试编号｛｝，测试用例标题｛｝，执行成功!
2021-12-07 17:50:21,731-[test_register.py - 52]-ERROR:测试编号｛｝，测试用例标题｛｝，执行成功!
2021-12-07 17:50:21,785-[test_register.py - 52]-ERROR:测试编号｛｝，测试用例标题｛｝，执行成功!
2021-12-07 17:54:42,949-[log_utils.py - 46]-WARNING:waring级别以上的日志信息
2021-12-07 17:54:42,949-[log_utils.py - 47]-ERROR:error级别以上的日志信息
2021-12-07 17:54:43,112-[test_register.py - 52]-ERROR:测试编号｛｝，测试用例标题｛｝，执行成功!
2021-12-07 17:54:43,179-[test_register.py - 52]-ERROR:测试编号｛｝，测试用例标题｛｝，执行成功!
2021-12-07 17:54:43,249-[test_register.py - 52]-ERROR:测试编号｛｝，测试用例标题｛｝，执行成功!
2021-12-07 17:54:43,303-[test_register.py - 52]-ERROR:测试编号｛｝，测试用例标题｛｝，执行成功!
2021-12-07 17:54:43,354-[test_register.py - 52]-ERROR:测试编号｛｝，测试用例标题｛｝，执行成功!
2021-12-07 17:56:02,685-[log_utils.py - 46]-WARNING:waring级别以上的日志信息
2021-12-07 17:56:02,686-[log_utils.py - 47]-ERROR:error级别以上的日志信息
2021-12-07 17:56:02,862-[test_register.py - 52]-INFO:测试编号｛｝，测试用例标题｛｝，执行成功!
2021-12-07 17:56:02,934-[test_register.py - 52]-INFO:测试编号｛｝，测试用例标题｛｝，执行成功!
2021-12-07 17:56:02,990-[test_register.py - 52]-INFO:测试编号｛｝，测试用例标题｛｝，执行成功!
2021-12-07 17:56:03,046-[test_register.py - 52]-INFO:测试编号｛｝，测试用例标题｛｝，执行成功!
2021-12-07 17:56:03,099-[test_register.py - 52]-INFO:测试编号｛｝，测试用例标题｛｝，执行成功!
2021-12-07 17:56:15,267-[log_utils.py - 46]-WARNING:waring级别以上的日志信息
2021-12-07 17:56:15,267-[log_utils.py - 47]-ERROR:error级别以上的日志信息
2021-12-07 17:56:15,414-[test_register.py - 52]-INFO:测试编号｛｝，测试用例标题｛｝，执行成功!
2021-12-07 17:56:15,488-[test_register.py - 52]-INFO:测试编号｛｝，测试用例标题｛｝，执行成功!
2021-12-07 17:56:15,539-[test_register.py - 52]-INFO:测试编号｛｝，测试用例标题｛｝，执行成功!
2021-12-07 17:56:15,592-[test_register.py - 52]-INFO:测试编号｛｝，测试用例标题｛｝，执行成功!
2021-12-07 17:56:15,648-[test_register.py - 52]-INFO:测试编号｛｝，测试用例标题｛｝，执行成功!
2021-12-07 17:56:35,784-[log_utils.py - 46]-WARNING:waring级别以上的日志信息
2021-12-07 17:56:35,785-[log_utils.py - 47]-ERROR:error级别以上的日志信息
2021-12-07 17:56:35,914-[test_login.py - 42]-INFO:测试编号1,测试用例标题登录接口主流程,执行成功!
2021-12-07 17:56:35,993-[test_login.py - 42]-INFO:测试编号2,测试用例标题登录接口输入错误用户名的场景,执行成功!
2021-12-07 17:56:36,053-[test_login.py - 42]-INFO:测试编号3,测试用例标题登录接口用户名为空的场景,执行成功!
2021-12-07 17:56:36,110-[test_login.py - 42]-INFO:测试编号4,测试用例标题登录接口密码输入错误的场景,执行成功!
2021-12-07 17:56:36,163-[test_login.py - 42]-INFO:测试编号5,测试用例标题登录接口密码为空的场景,执行成功!
2021-12-07 17:58:23,055-[log_utils.py - 46]-WARNING:waring级别以上的日志信息
2021-12-07 17:58:23,055-[log_utils.py - 47]-ERROR:error级别以上的日志信息
2021-12-07 17:58:23,169-[test_register.py - 52]-INFO:测试编号｛｝，测试用例标题｛｝，执行成功!
2021-12-07 17:58:23,235-[test_register.py - 52]-INFO:测试编号｛｝，测试用例标题｛｝，执行成功!
2021-12-07 17:58:23,289-[test_register.py - 52]-INFO:测试编号｛｝，测试用例标题｛｝，执行成功!
2021-12-07 17:58:23,343-[test_register.py - 52]-INFO:测试编号｛｝，测试用例标题｛｝，执行成功!
2021-12-07 17:58:23,394-[test_register.py - 52]-INFO:测试编号｛｝，测试用例标题｛｝，执行成功!
2021-12-07 18:25:49,207-[log_utils.py - 46]-WARNING:waring级别以上的日志信息
2021-12-07 18:25:49,208-[log_utils.py - 47]-ERROR:error级别以上的日志信息
2021-12-07 18:25:49,837-[test_login.py - 42]-INFO:测试编号1,测试用例标题登录接口主流程,执行成功!
2021-12-07 18:25:49,920-[test_login.py - 42]-INFO:测试编号2,测试用例标题登录接口输入错误用户名的场景,执行成功!
2021-12-07 18:25:49,981-[test_login.py - 42]-INFO:测试编号3,测试用例标题登录接口用户名为空的场景,执行成功!
2021-12-07 18:25:50,044-[test_login.py - 42]-INFO:测试编号4,测试用例标题登录接口密码输入错误的场景,执行成功!
2021-12-07 18:25:50,109-[test_login.py - 42]-INFO:测试编号5,测试用例标题登录接口密码为空的场景,执行成功!
2021-12-07 18:26:01,735-[log_utils.py - 46]-WARNING:waring级别以上的日志信息
2021-12-07 18:26:01,735-[log_utils.py - 47]-ERROR:error级别以上的日志信息
2021-12-07 18:26:01,847-[test_login.py - 42]-INFO:测试编号1,测试用例标题登录接口主流程,执行成功!
2021-12-07 18:26:01,927-[test_login.py - 42]-INFO:测试编号2,测试用例标题登录接口输入错误用户名的场景,执行成功!
2021-12-07 18:26:01,982-[test_login.py - 42]-INFO:测试编号3,测试用例标题登录接口用户名为空的场景,执行成功!
2021-12-07 18:26:02,037-[test_login.py - 42]-INFO:测试编号4,测试用例标题登录接口密码输入错误的场景,执行成功!
2021-12-07 18:26:02,096-[test_login.py - 42]-INFO:测试编号5,测试用例标题登录接口密码为空的场景,执行成功!
2021-12-07 18:26:13,031-[log_utils.py - 46]-WARNING:waring级别以上的日志信息
2021-12-07 18:26:13,031-[log_utils.py - 47]-ERROR:error级别以上的日志信息
2021-12-07 18:26:13,303-[test_login.py - 42]-INFO:测试编号1,测试用例标题登录接口主流程,执行成功!
2021-12-07 18:26:13,428-[test_login.py - 42]-INFO:测试编号2,测试用例标题登录接口输入错误用户名的场景,执行成功!
2021-12-07 18:26:13,545-[test_login.py - 42]-INFO:测试编号3,测试用例标题登录接口用户名为空的场景,执行成功!
2021-12-07 18:26:13,683-[test_login.py - 42]-INFO:测试编号4,测试用例标题登录接口密码输入错误的场景,执行成功!
2021-12-07 18:26:13,796-[test_login.py - 42]-INFO:测试编号5,测试用例标题登录接口密码为空的场景,执行成功!
2021-12-07 18:26:14,915-[log_utils.py - 46]-WARNING:waring级别以上的日志信息
2021-12-07 18:26:14,916-[log_utils.py - 47]-ERROR:error级别以上的日志信息
2021-12-07 18:26:15,053-[test_login.py - 42]-INFO:测试编号1,测试用例标题登录接口主流程,执行成功!
2021-12-07 18:26:15,133-[test_login.py - 42]-INFO:测试编号2,测试用例标题登录接口输入错误用户名的场景,执行成功!
2021-12-07 18:26:15,192-[test_login.py - 42]-INFO:测试编号3,测试用例标题登录接口用户名为空的场景,执行成功!
2021-12-07 18:26:15,246-[test_login.py - 42]-INFO:测试编号4,测试用例标题登录接口密码输入错误的场景,执行成功!
2021-12-07 18:26:15,306-[test_login.py - 42]-INFO:测试编号5,测试用例标题登录接口密码为空的场景,执行成功!
2021-12-07 18:26:18,215-[log_utils.py - 46]-WARNING:waring级别以上的日志信息
2021-12-07 18:26:18,215-[log_utils.py - 47]-ERROR:error级别以上的日志信息
2021-12-07 18:26:18,381-[test_login.py - 42]-INFO:测试编号1,测试用例标题登录接口主流程,执行成功!
2021-12-07 18:26:18,450-[test_login.py - 42]-INFO:测试编号2,测试用例标题登录接口输入错误用户名的场景,执行成功!
2021-12-07 18:26:18,506-[test_login.py - 42]-INFO:测试编号3,测试用例标题登录接口用户名为空的场景,执行成功!
2021-12-07 18:26:18,563-[test_login.py - 42]-INFO:测试编号4,测试用例标题登录接口密码输入错误的场景,执行成功!
2021-12-07 18:26:18,622-[test_login.py - 42]-INFO:测试编号5,测试用例标题登录接口密码为空的场景,执行成功!
2021-12-07 19:14:38,379-[log_utils.py - 46]-WARNING:waring级别以上的日志信息
2021-12-07 19:14:38,379-[log_utils.py - 47]-ERROR:error级别以上的日志信息
2021-12-07 19:14:58,194-[log_utils.py - 46]-WARNING:waring级别以上的日志信息
2021-12-07 19:14:58,194-[log_utils.py - 47]-ERROR:error级别以上的日志信息
2021-12-07 19:14:58,304-[test_login.py - 42]-INFO:测试编号1,测试用例标题登录接口主流程,执行成功!
2021-12-07 19:14:58,384-[test_login.py - 42]-INFO:测试编号2,测试用例标题登录接口输入错误用户名的场景,执行成功!
2021-12-07 19:14:58,436-[test_login.py - 42]-INFO:测试编号3,测试用例标题登录接口用户名为空的场景,执行成功!
2021-12-07 19:14:58,491-[test_login.py - 42]-INFO:测试编号4,测试用例标题登录接口密码输入错误的场景,执行成功!
2021-12-07 19:14:58,542-[test_login.py - 42]-INFO:测试编号5,测试用例标题登录接口密码为空的场景,执行成功!
2021-12-08 09:07:15,871-[log_utils.py - 46]-WARNING:waring级别以上的日志信息
2021-12-08 09:07:15,872-[log_utils.py - 47]-ERROR:error级别以上的日志信息
2021-12-08 09:10:02,010-[log_utils.py - 46]-WARNING:waring级别以上的日志信息
2021-12-08 09:10:02,010-[log_utils.py - 47]-ERROR:error级别以上的日志信息
2021-12-08 09:10:02,156-[test_login.py - 42]-INFO:测试编号1,测试用例标题登录接口主流程,执行成功!
2021-12-08 09:10:02,229-[test_login.py - 42]-INFO:测试编号2,测试用例标题登录接口输入错误用户名的场景,执行成功!
2021-12-08 09:10:02,280-[test_login.py - 42]-INFO:测试编号3,测试用例标题登录接口用户名为空的场景,执行成功!
2021-12-08 09:10:02,334-[test_login.py - 42]-INFO:测试编号4,测试用例标题登录接口密码输入错误的场景,执行成功!
2021-12-08 09:10:02,386-[test_login.py - 42]-INFO:测试编号5,测试用例标题登录接口密码为空的场景,执行成功!
2021-12-08 15:46:33,301-[log_utils.py - 46]-WARNING:waring级别以上的日志信息
2021-12-08 15:46:33,301-[log_utils.py - 47]-ERROR:error级别以上的日志信息
2021-12-08 15:47:14,964-[log_utils.py - 46]-WARNING:waring级别以上的日志信息
2021-12-08 15:47:14,964-[log_utils.py - 47]-ERROR:error级别以上的日志信息
2021-12-08 15:47:15,305-[test_login.py - 42]-INFO:测试编号1,测试用例标题登录接口主流程,执行成功!
2021-12-08 15:47:15,430-[test_login.py - 42]-INFO:测试编号2,测试用例标题登录接口输入错误用户名的场景,执行成功!
2021-12-08 15:47:15,549-[test_login.py - 42]-INFO:测试编号3,测试用例标题登录接口用户名为空的场景,执行成功!
2021-12-08 15:47:15,665-[test_login.py - 42]-INFO:测试编号4,测试用例标题登录接口密码输入错误的场景,执行成功!
2021-12-08 15:47:15,776-[test_login.py - 42]-INFO:测试编号5,测试用例标题登录接口密码为空的场景,执行成功!
2021-12-08 15:47:34,289-[log_utils.py - 46]-WARNING:waring级别以上的日志信息
2021-12-08 15:47:34,289-[log_utils.py - 47]-ERROR:error级别以上的日志信息
2021-12-08 15:47:34,532-[test_login.py - 42]-INFO:测试编号1,测试用例标题登录接口主流程,执行成功!
2021-12-08 15:47:34,653-[test_login.py - 42]-INFO:测试编号2,测试用例标题登录接口输入错误用户名的场景,执行成功!
2021-12-08 15:47:34,766-[test_login.py - 42]-INFO:测试编号3,测试用例标题登录接口用户名为空的场景,执行成功!
2021-12-08 15:47:34,886-[test_login.py - 42]-INFO:测试编号4,测试用例标题登录接口密码输入错误的场景,执行成功!
2021-12-08 15:47:35,001-[test_login.py - 42]-INFO:测试编号5,测试用例标题登录接口密码为空的场景,执行成功!
2021-12-08 15:48:00,368-[log_utils.py - 46]-WARNING:waring级别以上的日志信息
2021-12-08 15:48:00,368-[log_utils.py - 47]-ERROR:error级别以上的日志信息
2021-12-08 15:48:07,513-[log_utils.py - 46]-WARNING:waring级别以上的日志信息
2021-12-08 15:48:07,513-[log_utils.py - 47]-ERROR:error级别以上的日志信息
2021-12-08 15:48:07,781-[test_login.py - 42]-INFO:测试编号1,测试用例标题登录接口主流程,执行成功!
2021-12-08 15:48:07,907-[test_login.py - 42]-INFO:测试编号2,测试用例标题登录接口输入错误用户名的场景,执行成功!
2021-12-08 15:48:08,027-[test_login.py - 42]-INFO:测试编号3,测试用例标题登录接口用户名为空的场景,执行成功!
2021-12-08 15:48:08,143-[test_login.py - 42]-INFO:测试编号4,测试用例标题登录接口密码输入错误的场景,执行成功!
2021-12-08 15:48:08,280-[test_login.py - 42]-INFO:测试编号5,测试用例标题登录接口密码为空的场景,执行成功!
2021-12-08 15:48:32,782-[log_utils.py - 46]-WARNING:waring级别以上的日志信息
2021-12-08 15:48:32,782-[log_utils.py - 47]-ERROR:error级别以上的日志信息
2021-12-08 15:50:26,443-[log_utils.py - 46]-WARNING:waring级别以上的日志信息
2021-12-08 15:50:26,443-[log_utils.py - 47]-ERROR:error级别以上的日志信息
2021-12-08 15:51:06,356-[log_utils.py - 46]-WARNING:waring级别以上的日志信息
2021-12-08 15:51:06,357-[log_utils.py - 47]-ERROR:error级别以上的日志信息
2021-12-08 15:51:20,762-[log_utils.py - 46]-WARNING:waring级别以上的日志信息
2021-12-08 15:51:20,762-[log_utils.py - 47]-ERROR:error级别以上的日志信息
2021-12-08 15:52:22,321-[test_login.py - 42]-INFO:测试编号1,测试用例标题登录接口主流程,执行成功!
2021-12-08 15:52:38,773-[log_utils.py - 46]-WARNING:waring级别以上的日志信息
2021-12-08 15:52:38,773-[log_utils.py - 47]-ERROR:error级别以上的日志信息
2021-12-08 15:53:03,083-[log_utils.py - 46]-WARNING:waring级别以上的日志信息
2021-12-08 15:53:03,083-[log_utils.py - 47]-ERROR:error级别以上的日志信息
2021-12-08 15:53:03,331-[test_login.py - 42]-INFO:测试编号1,测试用例标题登录接口主流程,执行成功!
2021-12-08 15:53:03,446-[test_login.py - 42]-INFO:测试编号2,测试用例标题登录接口输入错误用户名的场景,执行成功!
2021-12-08 15:53:03,562-[test_login.py - 42]-INFO:测试编号3,测试用例标题登录接口用户名为空的场景,执行成功!
2021-12-08 15:53:03,705-[test_login.py - 42]-INFO:测试编号4,测试用例标题登录接口密码输入错误的场景,执行成功!
2021-12-08 15:53:03,825-[test_login.py - 42]-INFO:测试编号5,测试用例标题登录接口密码为空的场景,执行成功!
2021-12-08 15:54:06,586-[log_utils.py - 46]-WARNING:waring级别以上的日志信息
2021-12-08 15:54:06,586-[log_utils.py - 47]-ERROR:error级别以上的日志信息
2021-12-08 15:54:39,591-[test_login.py - 42]-INFO:测试编号1,测试用例标题登录接口主流程,执行成功!
2021-12-08 15:55:52,216-[test_login.py - 42]-INFO:测试编号2,测试用例标题登录接口输入错误用户名的场景,执行成功!
2021-12-08 15:56:29,028-[log_utils.py - 46]-WARNING:waring级别以上的日志信息
2021-12-08 15:56:29,028-[log_utils.py - 47]-ERROR:error级别以上的日志信息
2021-12-08 15:58:36,424-[test_login.py - 42]-INFO:测试编号1,测试用例标题登录接口主流程,执行成功!
2021-12-08 15:59:17,778-[log_utils.py - 46]-WARNING:waring级别以上的日志信息
2021-12-08 15:59:17,778-[log_utils.py - 47]-ERROR:error级别以上的日志信息
2021-12-08 15:59:18,069-[test_login.py - 42]-INFO:测试编号1,测试用例标题登录接口主流程,执行成功!
2021-12-08 15:59:18,205-[test_login.py - 42]-INFO:测试编号2,测试用例标题登录接口输入错误用户名的场景,执行成功!
2021-12-08 15:59:18,321-[test_login.py - 42]-INFO:测试编号3,测试用例标题登录接口用户名为空的场景,执行成功!
2021-12-08 15:59:18,432-[test_login.py - 42]-INFO:测试编号4,测试用例标题登录接口密码输入错误的场景,执行成功!
2021-12-08 15:59:18,556-[test_login.py - 42]-INFO:测试编号5,测试用例标题登录接口密码为空的场景,执行成功!
2021-12-08 15:59:41,292-[log_utils.py - 46]-WARNING:waring级别以上的日志信息
2021-12-08 15:59:41,292-[log_utils.py - 47]-ERROR:error级别以上的日志信息
2021-12-08 16:26:15,071-[log_utils.py - 46]-WARNING:waring级别以上的日志信息
2021-12-08 16:26:15,071-[log_utils.py - 47]-ERROR:error级别以上的日志信息
2021-12-08 16:27:05,500-[log_utils.py - 46]-WARNING:waring级别以上的日志信息
2021-12-08 16:27:05,500-[log_utils.py - 47]-ERROR:error级别以上的日志信息
2021-12-08 16:27:29,964-[log_utils.py - 46]-WARNING:waring级别以上的日志信息
2021-12-08 16:27:29,964-[log_utils.py - 47]-ERROR:error级别以上的日志信息
2021-12-08 16:28:16,307-[log_utils.py - 46]-WARNING:waring级别以上的日志信息
2021-12-08 16:28:16,307-[log_utils.py - 47]-ERROR:error级别以上的日志信息
2021-12-08 16:34:07,704-[log_utils.py - 46]-WARNING:waring级别以上的日志信息
2021-12-08 16:34:07,704-[log_utils.py - 47]-ERROR:error级别以上的日志信息
2021-12-08 16:37:27,634-[log_utils.py - 46]-WARNING:waring级别以上的日志信息
2021-12-08 16:37:27,634-[log_utils.py - 47]-ERROR:error级别以上的日志信息
2021-12-08 16:37:27,809-[test_login.py - 42]-INFO:测试编号1,测试用例标题登录接口主流程,执行成功!
2021-12-08 16:37:27,879-[test_login.py - 42]-INFO:测试编号2,测试用例标题登录接口输入错误用户名的场景,执行成功!
2021-12-08 16:37:27,932-[test_login.py - 42]-INFO:测试编号3,测试用例标题登录接口用户名为空的场景,执行成功!
2021-12-08 16:37:27,990-[test_login.py - 42]-INFO:测试编号4,测试用例标题登录接口密码输入错误的场景,执行成功!
2021-12-08 16:37:28,051-[test_login.py - 36]-ERROR:测试编号5,测试用例标题登录接口密码为空的场景,执行失败!实际结果{'code': 1003, 'msg': '用户名或者密码错误'}
2021-12-08 16:37:28,051-[test_login.py - 37]-ERROR:{'code': 1002, 'msg': '密码不能为空'} != {'code': 1003, 'msg': '用户名或者密码错误'}
- {'code': 1002, 'msg': '密码不能为空'}
?             ^            ^^^^

+ {'code': 1003, 'msg': '用户名或者密码错误'}
?             ^          +++++  ^^
Traceback (most recent call last):
  File "D:\PythonWorkSpace\day16\homework\test_login.py", line 33, in test_login
    self.assertEqual(eval(case.expect), res_body)  # assert 断言的意思，Equal是相等的意思
  File "D:\python\PyCharm Community Edition 2021.2.3\plugins\python-ce\helpers\pycharm\teamcity\diff_tools.py", line 32, in _patched_equals
    old(self, first, second, msg)
  File "C:\Program Files\Python37\lib\unittest\case.py", line 839, in assertEqual
    assertion_func(first, second, msg=msg)
  File "C:\Program Files\Python37\lib\unittest\case.py", line 1138, in assertDictEqual
    self.fail(self._formatMessage(msg, standardMsg))
  File "C:\Program Files\Python37\lib\unittest\case.py", line 680, in fail
    raise self.failureException(msg)
AssertionError: {'code': 1002, 'msg': '密码不能为空'} != {'code': 1003, 'msg': '用户名或者密码错误'}
- {'code': 1002, 'msg': '密码不能为空'}
?             ^            ^^^^

+ {'code': 1003, 'msg': '用户名或者密码错误'}
?             ^          +++++  ^^

2021-12-08 16:37:38,391-[log_utils.py - 46]-WARNING:waring级别以上的日志信息
2021-12-08 16:37:38,391-[log_utils.py - 47]-ERROR:error级别以上的日志信息
2021-12-08 16:37:48,992-[test_login.py - 42]-INFO:测试编号1,测试用例标题登录接口主流程,执行成功!
2021-12-08 16:37:58,568-[test_login.py - 42]-INFO:测试编号2,测试用例标题登录接口输入错误用户名的场景,执行成功!
2021-12-08 16:38:45,518-[test_login.py - 42]-INFO:测试编号3,测试用例标题登录接口用户名为空的场景,执行成功!
2021-12-08 16:39:08,533-[test_login.py - 42]-INFO:测试编号4,测试用例标题登录接口密码输入错误的场景,执行成功!
2021-12-08 16:39:43,410-[test_login.py - 36]-ERROR:测试编号5,测试用例标题登录接口密码为空的场景,执行失败!实际结果{'code': 1003, 'msg': '用户名或者密码错误'}
2021-12-08 16:39:43,411-[test_login.py - 37]-ERROR:{'code': 1002, 'msg': '密码不能为空'} != {'code': 1003, 'msg': '用户名或者密码错误'}
- {'code': 1002, 'msg': '密码不能为空'}
?             ^            ^^^^

+ {'code': 1003, 'msg': '用户名或者密码错误'}
?             ^          +++++  ^^
Traceback (most recent call last):
  File "D:\PythonWorkSpace\day16\homework\test_login.py", line 33, in test_login
    self.assertEqual(eval(case.expect), res_body)  # assert 断言的意思，Equal是相等的意思
  File "D:\python\PyCharm Community Edition 2021.2.3\plugins\python-ce\helpers\pycharm\teamcity\diff_tools.py", line 32, in _patched_equals
    old(self, first, second, msg)
  File "C:\Program Files\Python37\lib\unittest\case.py", line 839, in assertEqual
    assertion_func(first, second, msg=msg)
  File "C:\Program Files\Python37\lib\unittest\case.py", line 1138, in assertDictEqual
    self.fail(self._formatMessage(msg, standardMsg))
  File "C:\Program Files\Python37\lib\unittest\case.py", line 680, in fail
    raise self.failureException(msg)
AssertionError: {'code': 1002, 'msg': '密码不能为空'} != {'code': 1003, 'msg': '用户名或者密码错误'}
- {'code': 1002, 'msg': '密码不能为空'}
?             ^            ^^^^

+ {'code': 1003, 'msg': '用户名或者密码错误'}
?             ^          +++++  ^^

2021-12-08 16:39:51,048-[log_utils.py - 46]-WARNING:waring级别以上的日志信息
2021-12-08 16:39:51,048-[log_utils.py - 47]-ERROR:error级别以上的日志信息
2021-12-08 16:39:54,410-[test_login.py - 42]-INFO:测试编号1,测试用例标题登录接口主流程,执行成功!
2021-12-08 16:40:24,602-[test_login.py - 42]-INFO:测试编号2,测试用例标题登录接口输入错误用户名的场景,执行成功!
2021-12-08 16:40:46,582-[test_login.py - 42]-INFO:测试编号3,测试用例标题登录接口用户名为空的场景,执行成功!
2021-12-08 16:41:10,045-[test_login.py - 42]-INFO:测试编号4,测试用例标题登录接口密码输入错误的场景,执行成功!
2021-12-08 16:43:03,266-[test_login.py - 36]-ERROR:测试编号5,测试用例标题登录接口密码为空的场景,执行失败!实际结果{'code': 1003, 'msg': '用户名或者密码错误'}
2021-12-08 16:43:07,941-[test_login.py - 37]-ERROR:{'code': 1002, 'msg': '密码不能为空'} != {'code': 1003, 'msg': '用户名或者密码错误'}
- {'code': 1002, 'msg': '密码不能为空'}
?             ^            ^^^^

+ {'code': 1003, 'msg': '用户名或者密码错误'}
?             ^          +++++  ^^
Traceback (most recent call last):
  File "D:\PythonWorkSpace\day16\homework\test_login.py", line 33, in test_login
    self.assertEqual(eval(case.expect), res_body)  # assert 断言的意思，Equal是相等的意思
  File "D:\python\PyCharm Community Edition 2021.2.3\plugins\python-ce\helpers\pycharm\teamcity\diff_tools.py", line 32, in _patched_equals
    old(self, first, second, msg)
  File "C:\Program Files\Python37\lib\unittest\case.py", line 839, in assertEqual
    assertion_func(first, second, msg=msg)
  File "C:\Program Files\Python37\lib\unittest\case.py", line 1138, in assertDictEqual
    self.fail(self._formatMessage(msg, standardMsg))
  File "C:\Program Files\Python37\lib\unittest\case.py", line 680, in fail
    raise self.failureException(msg)
AssertionError: {'code': 1002, 'msg': '密码不能为空'} != {'code': 1003, 'msg': '用户名或者密码错误'}
- {'code': 1002, 'msg': '密码不能为空'}
?             ^            ^^^^

+ {'code': 1003, 'msg': '用户名或者密码错误'}
?             ^          +++++  ^^

2021-12-08 16:44:21,895-[log_utils.py - 46]-WARNING:waring级别以上的日志信息
2021-12-08 16:44:21,895-[log_utils.py - 47]-ERROR:error级别以上的日志信息
2021-12-08 16:44:50,367-[log_utils.py - 46]-WARNING:waring级别以上的日志信息
2021-12-08 16:44:50,368-[log_utils.py - 47]-ERROR:error级别以上的日志信息
2021-12-08 16:45:29,054-[test_login.py - 42]-INFO:测试编号1,测试用例标题登录接口主流程,执行成功!
2021-12-08 17:01:42,983-[log_utils.py - 46]-WARNING:waring级别以上的日志信息
2021-12-08 17:01:42,984-[log_utils.py - 47]-ERROR:error级别以上的日志信息
2021-12-08 17:02:33,577-[log_utils.py - 46]-WARNING:waring级别以上的日志信息
2021-12-08 17:02:33,577-[log_utils.py - 47]-ERROR:error级别以上的日志信息
2021-12-08 17:02:33,787-[test_login.py - 42]-INFO:测试编号1,测试用例标题登录接口主流程,执行成功!
2021-12-08 17:02:33,885-[test_login.py - 42]-INFO:测试编号2,测试用例标题登录接口输入错误用户名的场景,执行成功!
2021-12-08 17:02:33,948-[test_login.py - 42]-INFO:测试编号3,测试用例标题登录接口用户名为空的场景,执行成功!
2021-12-08 17:02:34,026-[test_login.py - 42]-INFO:测试编号4,测试用例标题登录接口密码输入错误的场景,执行成功!
2021-12-08 17:02:34,104-[test_login.py - 42]-INFO:测试编号5,测试用例标题登录接口密码为空的场景,执行成功!
2021-12-08 17:02:46,491-[log_utils.py - 46]-WARNING:waring级别以上的日志信息
2021-12-08 17:02:46,491-[log_utils.py - 47]-ERROR:error级别以上的日志信息
2021-12-08 17:02:46,630-[test_login.py - 42]-INFO:测试编号1,测试用例标题登录接口主流程,执行成功!
2021-12-08 17:02:46,701-[test_login.py - 42]-INFO:测试编号2,测试用例标题登录接口输入错误用户名的场景,执行成功!
2021-12-08 17:02:46,754-[test_login.py - 42]-INFO:测试编号3,测试用例标题登录接口用户名为空的场景,执行成功!
2021-12-08 17:02:46,809-[test_login.py - 42]-INFO:测试编号4,测试用例标题登录接口密码输入错误的场景,执行成功!
2021-12-08 17:02:46,863-[test_login.py - 42]-INFO:测试编号5,测试用例标题登录接口密码为空的场景,执行成功!
2021-12-08 17:03:24,794-[log_utils.py - 46]-WARNING:waring级别以上的日志信息
2021-12-08 17:03:24,794-[log_utils.py - 47]-ERROR:error级别以上的日志信息
2021-12-08 17:03:24,944-[test_login.py - 42]-INFO:测试编号1,测试用例标题登录接口主流程,执行成功!
2021-12-08 17:03:25,012-[test_login.py - 42]-INFO:测试编号2,测试用例标题登录接口输入错误用户名的场景,执行成功!
2021-12-08 17:03:25,062-[test_login.py - 42]-INFO:测试编号3,测试用例标题登录接口用户名为空的场景,执行成功!
2021-12-08 17:03:25,131-[test_login.py - 42]-INFO:测试编号4,测试用例标题登录接口密码输入错误的场景,执行成功!
2021-12-08 17:03:25,181-[test_login.py - 42]-INFO:测试编号5,测试用例标题登录接口密码为空的场景,执行成功!
2021-12-08 17:04:00,230-[log_utils.py - 46]-WARNING:waring级别以上的日志信息
2021-12-08 17:04:00,230-[log_utils.py - 47]-ERROR:error级别以上的日志信息
2021-12-08 17:04:00,384-[test_login.py - 42]-INFO:测试编号1,测试用例标题登录接口主流程,执行成功!
2021-12-08 17:04:00,449-[test_login.py - 42]-INFO:测试编号2,测试用例标题登录接口输入错误用户名的场景,执行成功!
2021-12-08 17:04:00,499-[test_login.py - 42]-INFO:测试编号3,测试用例标题登录接口用户名为空的场景,执行成功!
2021-12-08 17:04:00,560-[test_login.py - 42]-INFO:测试编号4,测试用例标题登录接口密码输入错误的场景,执行成功!
2021-12-08 17:04:00,612-[test_login.py - 42]-INFO:测试编号5,测试用例标题登录接口密码为空的场景,执行成功!
2021-12-08 17:04:37,719-[log_utils.py - 46]-WARNING:waring级别以上的日志信息
2021-12-08 17:04:37,719-[log_utils.py - 47]-ERROR:error级别以上的日志信息
2021-12-08 17:05:06,746-[log_utils.py - 46]-WARNING:waring级别以上的日志信息
2021-12-08 17:05:06,746-[log_utils.py - 47]-ERROR:error级别以上的日志信息
2021-12-08 17:05:06,877-[test_login.py - 42]-INFO:测试编号1,测试用例标题登录接口主流程,执行成功!
2021-12-08 17:05:06,946-[test_login.py - 42]-INFO:测试编号2,测试用例标题登录接口输入错误用户名的场景,执行成功!
2021-12-08 17:05:06,998-[test_login.py - 42]-INFO:测试编号3,测试用例标题登录接口用户名为空的场景,执行成功!
2021-12-08 17:05:07,053-[test_login.py - 42]-INFO:测试编号4,测试用例标题登录接口密码输入错误的场景,执行成功!
2021-12-08 17:05:07,107-[test_login.py - 42]-INFO:测试编号5,测试用例标题登录接口密码为空的场景,执行成功!
2021-12-08 17:06:30,909-[log_utils.py - 46]-WARNING:waring级别以上的日志信息
2021-12-08 17:06:30,909-[log_utils.py - 47]-ERROR:error级别以上的日志信息
2021-12-08 17:08:47,839-[log_utils.py - 46]-WARNING:waring级别以上的日志信息
2021-12-08 17:08:47,839-[log_utils.py - 47]-ERROR:error级别以上的日志信息
2021-12-08 17:08:48,016-[test_login.py - 42]-INFO:测试编号1,测试用例标题登录接口主流程,执行成功!
2021-12-08 17:08:48,085-[test_login.py - 42]-INFO:测试编号2,测试用例标题登录接口输入错误用户名的场景,执行成功!
2021-12-08 17:08:48,142-[test_login.py - 42]-INFO:测试编号3,测试用例标题登录接口用户名为空的场景,执行成功!
2021-12-08 17:08:48,227-[test_login.py - 42]-INFO:测试编号4,测试用例标题登录接口密码输入错误的场景,执行成功!
2021-12-08 17:08:48,295-[test_login.py - 36]-ERROR:测试编号5,测试用例标题登录接口密码为空的场景,执行失败!实际结果{'code': 1003, 'msg': '用户名或者密码错误'}
2021-12-08 17:08:48,295-[test_login.py - 37]-ERROR:{'code': 1002, 'msg': '密码不能为空'} != {'code': 1003, 'msg': '用户名或者密码错误'}
- {'code': 1002, 'msg': '密码不能为空'}
?             ^            ^^^^

+ {'code': 1003, 'msg': '用户名或者密码错误'}
?             ^          +++++  ^^
Traceback (most recent call last):
  File "D:\PythonWorkSpace\day16\homework\test_login.py", line 33, in test_login
    self.assertEqual(eval(case.expect), res_body)  # assert 断言的意思，Equal是相等的意思
  File "D:\python\PyCharm Community Edition 2021.2.3\plugins\python-ce\helpers\pycharm\teamcity\diff_tools.py", line 32, in _patched_equals
    old(self, first, second, msg)
  File "C:\Program Files\Python37\lib\unittest\case.py", line 839, in assertEqual
    assertion_func(first, second, msg=msg)
  File "C:\Program Files\Python37\lib\unittest\case.py", line 1138, in assertDictEqual
    self.fail(self._formatMessage(msg, standardMsg))
  File "C:\Program Files\Python37\lib\unittest\case.py", line 680, in fail
    raise self.failureException(msg)
AssertionError: {'code': 1002, 'msg': '密码不能为空'} != {'code': 1003, 'msg': '用户名或者密码错误'}
- {'code': 1002, 'msg': '密码不能为空'}
?             ^            ^^^^

+ {'code': 1003, 'msg': '用户名或者密码错误'}
?             ^          +++++  ^^

2021-12-08 17:09:07,476-[log_utils.py - 46]-WARNING:waring级别以上的日志信息
2021-12-08 17:09:07,476-[log_utils.py - 47]-ERROR:error级别以上的日志信息
2021-12-08 17:09:07,613-[test_login.py - 42]-INFO:测试编号1,测试用例标题登录接口主流程,执行成功!
2021-12-08 17:09:07,680-[test_login.py - 42]-INFO:测试编号2,测试用例标题登录接口输入错误用户名的场景,执行成功!
2021-12-08 17:09:07,734-[test_login.py - 42]-INFO:测试编号3,测试用例标题登录接口用户名为空的场景,执行成功!
2021-12-08 17:09:07,789-[test_login.py - 42]-INFO:测试编号4,测试用例标题登录接口密码输入错误的场景,执行成功!
2021-12-08 17:09:07,848-[test_login.py - 42]-INFO:测试编号5,测试用例标题登录接口密码为空的场景,执行成功!
2021-12-08 17:12:45,054-[log_utils.py - 46]-WARNING:waring级别以上的日志信息
2021-12-08 17:12:45,054-[log_utils.py - 47]-ERROR:error级别以上的日志信息
2021-12-08 17:12:45,179-[test_login.py - 42]-INFO:测试编号1,测试用例标题登录接口主流程,执行成功!
2021-12-08 17:12:45,249-[test_login.py - 42]-INFO:测试编号2,测试用例标题登录接口输入错误用户名的场景,执行成功!
2021-12-08 17:12:45,300-[test_login.py - 42]-INFO:测试编号3,测试用例标题登录接口用户名为空的场景,执行成功!
2021-12-08 17:12:45,358-[test_login.py - 42]-INFO:测试编号4,测试用例标题登录接口密码输入错误的场景,执行成功!
2021-12-08 17:12:45,413-[test_login.py - 42]-INFO:测试编号5,测试用例标题登录接口密码为空的场景,执行成功!
2021-12-08 17:13:55,120-[log_utils.py - 46]-WARNING:waring级别以上的日志信息
2021-12-08 17:13:55,121-[log_utils.py - 47]-ERROR:error级别以上的日志信息
2021-12-08 17:13:55,256-[test_login.py - 42]-INFO:测试编号1,测试用例标题登录接口主流程,执行成功!
2021-12-08 17:13:55,328-[test_login.py - 42]-INFO:测试编号2,测试用例标题登录接口输入错误用户名的场景,执行成功!
2021-12-08 17:13:55,383-[test_login.py - 42]-INFO:测试编号3,测试用例标题登录接口用户名为空的场景,执行成功!
2021-12-08 17:13:55,446-[test_login.py - 36]-ERROR:测试编号4,测试用例标题登录接口密码输入错误的场景,执行失败!实际结果{'code': 9999, 'msg': '登录成功'}
2021-12-08 17:13:55,446-[test_login.py - 37]-ERROR:{'code': 1003, 'msg': '用户名或者密码错误'} != {'code': 9999, 'msg': '登录成功'}
- {'code': 1003, 'msg': '用户名或者密码错误'}
+ {'code': 9999, 'msg': '登录成功'}
Traceback (most recent call last):
  File "D:\PythonWorkSpace\day16\homework\test_login.py", line 33, in test_login
    self.assertEqual(eval(case.expect), res_body)  # assert 断言的意思，Equal是相等的意思
  File "D:\python\PyCharm Community Edition 2021.2.3\plugins\python-ce\helpers\pycharm\teamcity\diff_tools.py", line 32, in _patched_equals
    old(self, first, second, msg)
  File "C:\Program Files\Python37\lib\unittest\case.py", line 839, in assertEqual
    assertion_func(first, second, msg=msg)
  File "C:\Program Files\Python37\lib\unittest\case.py", line 1138, in assertDictEqual
    self.fail(self._formatMessage(msg, standardMsg))
  File "C:\Program Files\Python37\lib\unittest\case.py", line 680, in fail
    raise self.failureException(msg)
AssertionError: {'code': 1003, 'msg': '用户名或者密码错误'} != {'code': 9999, 'msg': '登录成功'}
- {'code': 1003, 'msg': '用户名或者密码错误'}
+ {'code': 9999, 'msg': '登录成功'}
2021-12-08 17:13:55,501-[test_login.py - 42]-INFO:测试编号5,测试用例标题登录接口密码为空的场景,执行成功!
2021-12-08 17:14:13,443-[log_utils.py - 46]-WARNING:waring级别以上的日志信息
2021-12-08 17:14:13,444-[log_utils.py - 47]-ERROR:error级别以上的日志信息
2021-12-08 17:14:13,568-[test_login.py - 42]-INFO:测试编号1,测试用例标题登录接口主流程,执行成功!
2021-12-08 17:14:13,634-[test_login.py - 42]-INFO:测试编号2,测试用例标题登录接口输入错误用户名的场景,执行成功!
2021-12-08 17:14:13,685-[test_login.py - 42]-INFO:测试编号3,测试用例标题登录接口用户名为空的场景,执行成功!
2021-12-08 17:14:13,745-[test_login.py - 42]-INFO:测试编号4,测试用例标题登录接口密码输入错误的场景,执行成功!
2021-12-08 17:14:13,799-[test_login.py - 42]-INFO:测试编号5,测试用例标题登录接口密码为空的场景,执行成功!
2021-12-08 18:52:52,167-[log_utils.py - 46]-WARNING:waring级别以上的日志信息
2021-12-08 18:52:52,167-[log_utils.py - 47]-ERROR:error级别以上的日志信息
2021-12-08 18:52:52,334-[test_login.py - 42]-INFO:测试编号3,测试用例标题登录接口用户名为空的场景,执行成功!
2021-12-08 18:52:52,424-[test_login.py - 42]-INFO:测试编号5,测试用例标题登录接口密码为空的场景,执行成功!
2021-12-08 18:55:12,676-[log_utils.py - 46]-WARNING:waring级别以上的日志信息
2021-12-08 18:55:12,676-[log_utils.py - 47]-ERROR:error级别以上的日志信息
2021-12-08 18:55:21,131-[log_utils.py - 46]-WARNING:waring级别以上的日志信息
2021-12-08 18:55:21,131-[log_utils.py - 47]-ERROR:error级别以上的日志信息
2021-12-08 18:55:21,286-[test_login.py - 42]-INFO:测试编号3,测试用例标题登录接口用户名为空的场景,执行成功!
2021-12-08 18:55:21,361-[test_login.py - 42]-INFO:测试编号5,测试用例标题登录接口密码为空的场景,执行成功!
2021-12-08 18:56:41,182-[log_utils.py - 46]-WARNING:waring级别以上的日志信息
2021-12-08 18:56:41,182-[log_utils.py - 47]-ERROR:error级别以上的日志信息
2021-12-08 18:56:41,408-[test_login.py - 42]-INFO:测试编号3,测试用例标题登录接口用户名为空的场景,执行成功!
2021-12-08 18:56:41,489-[test_login.py - 42]-INFO:测试编号5,测试用例标题登录接口密码为空的场景,执行成功!
2021-12-08 18:56:48,249-[log_utils.py - 46]-WARNING:waring级别以上的日志信息
2021-12-08 18:56:48,249-[log_utils.py - 47]-ERROR:error级别以上的日志信息
2021-12-08 18:56:48,385-[test_register.py - 52]-INFO:测试编号｛｝，测试用例标题｛｝，执行成功!
2021-12-08 18:56:48,451-[test_register.py - 52]-INFO:测试编号｛｝，测试用例标题｛｝，执行成功!
2021-12-08 18:56:48,503-[test_register.py - 52]-INFO:测试编号｛｝，测试用例标题｛｝，执行成功!
2021-12-08 18:56:48,562-[test_register.py - 52]-INFO:测试编号｛｝，测试用例标题｛｝，执行成功!
2021-12-08 18:57:58,458-[log_utils.py - 46]-WARNING:waring级别以上的日志信息
2021-12-08 18:57:58,458-[log_utils.py - 47]-ERROR:error级别以上的日志信息
2021-12-08 18:58:07,527-[log_utils.py - 46]-WARNING:waring级别以上的日志信息
2021-12-08 18:58:07,527-[log_utils.py - 47]-ERROR:error级别以上的日志信息
2021-12-08 18:58:07,668-[test_login.py - 42]-INFO:测试编号3,测试用例标题登录接口用户名为空的场景,执行成功!
2021-12-08 18:58:07,745-[test_login.py - 42]-INFO:测试编号5,测试用例标题登录接口密码为空的场景,执行成功!
2021-12-08 18:59:37,421-[log_utils.py - 46]-WARNING:waring级别以上的日志信息
2021-12-08 18:59:37,421-[log_utils.py - 47]-ERROR:error级别以上的日志信息
2021-12-08 18:59:37,572-[test_login.py - 42]-INFO:测试编号3,测试用例标题登录接口用户名为空的场景,执行成功!
2021-12-08 18:59:37,670-[test_login.py - 42]-INFO:测试编号5,测试用例标题登录接口密码为空的场景,执行成功!
2021-12-08 19:01:24,483-[log_utils.py - 46]-WARNING:waring级别以上的日志信息
2021-12-08 19:01:24,484-[log_utils.py - 47]-ERROR:error级别以上的日志信息
2021-12-08 19:01:38,464-[log_utils.py - 46]-WARNING:waring级别以上的日志信息
2021-12-08 19:01:38,464-[log_utils.py - 47]-ERROR:error级别以上的日志信息
2021-12-08 19:01:52,963-[log_utils.py - 46]-WARNING:waring级别以上的日志信息
2021-12-08 19:01:52,963-[log_utils.py - 47]-ERROR:error级别以上的日志信息
2021-12-08 19:01:53,120-[test_login.py - 42]-INFO:测试编号3,测试用例标题登录接口用户名为空的场景,执行成功!
2021-12-08 19:01:53,207-[test_login.py - 42]-INFO:测试编号5,测试用例标题登录接口密码为空的场景,执行成功!
2021-12-08 19:03:03,433-[log_utils.py - 46]-WARNING:waring级别以上的日志信息
2021-12-08 19:03:03,433-[log_utils.py - 47]-ERROR:error级别以上的日志信息
2021-12-08 19:09:26,994-[log_utils.py - 46]-WARNING:waring级别以上的日志信息
2021-12-08 19:09:26,994-[log_utils.py - 47]-ERROR:error级别以上的日志信息
2021-12-08 19:09:27,164-[test_login.py - 42]-INFO:测试编号3,测试用例标题登录接口用户名为空的场景,执行成功!
2021-12-08 19:09:27,245-[test_login.py - 42]-INFO:测试编号5,测试用例标题登录接口密码为空的场景,执行成功!
2021-12-08 19:11:05,124-[log_utils.py - 46]-WARNING:waring级别以上的日志信息
2021-12-08 19:11:05,124-[log_utils.py - 47]-ERROR:error级别以上的日志信息
2021-12-08 19:11:05,919-[test_register.py - 52]-INFO:测试编号｛｝，测试用例标题｛｝，执行成功!
2021-12-08 19:11:06,030-[test_register.py - 52]-INFO:测试编号｛｝，测试用例标题｛｝，执行成功!
2021-12-08 19:11:06,093-[test_register.py - 52]-INFO:测试编号｛｝，测试用例标题｛｝，执行成功!
2021-12-08 19:11:06,146-[test_register.py - 52]-INFO:测试编号｛｝，测试用例标题｛｝，执行成功!
2021-12-08 19:11:06,202-[test_register.py - 52]-INFO:测试编号｛｝，测试用例标题｛｝，执行成功!
2021-12-08 19:11:12,141-[log_utils.py - 46]-WARNING:waring级别以上的日志信息
2021-12-08 19:11:12,141-[log_utils.py - 47]-ERROR:error级别以上的日志信息
2021-12-08 19:11:12,279-[test_login.py - 41]-INFO:测试编号1,测试用例标题登录接口主流程,执行成功!
2021-12-08 19:11:12,366-[test_login.py - 41]-INFO:测试编号2,测试用例标题登录接口输入错误用户名的场景,执行成功!
2021-12-08 19:11:12,419-[test_login.py - 41]-INFO:测试编号3,测试用例标题登录接口用户名为空的场景,执行成功!
2021-12-08 19:11:12,473-[test_login.py - 41]-INFO:测试编号4,测试用例标题登录接口密码输入错误的场景,执行成功!
2021-12-08 19:11:12,539-[test_login.py - 41]-INFO:测试编号5,测试用例标题登录接口密码为空的场景,执行成功!
